<mujoco model="template">
  <!-- This model has been converted from an OpenSim model. Model conversion by MyoConverter https://github.com/MyoHub/myoconverter. This model is licensed under Apache 2.0. -->
  <!-- Note: inertiagrouprange="0 1" means that groups 0-1 will be used to infer masses/inertias, and groups 2-5 are
  only for visualisation (e.g. wrapping objects) !-->
  <compiler inertiafromgeom="auto" angle="radian" balanceinertia="true" boundmass="0.001" boundinertia="0.001" inertiagrouprange="0 1">
    <lengthrange inttotal="50" useexisting="true"/>
  </compiler>
  <option collision="predefined"/>
  <visual>
    <scale framelength="0.5" framewidth="0.01"/>
  </visual>
  <default>
    <joint limited="true" damping="0.05" armature="0.00001" stiffness="0"/>
    <geom rgba="0.8 0.6 .4 1" margin="0.001"/>
    <site size="0.001"/>
    <tendon width="0.005" rgba=".95 .3 .3 1" limited="false"/>
    <default class="muscle">
      <muscle ctrllimited="true" ctrlrange="0 1" scale="200"/>
    </default>
    <default class="motor">
      <general gainprm="5 0 0 0 0 0 0 0 0 0"/>
    </default>
  </default>
  <option timestep="0.002"/>
  <!-- nuser_jnt=1, the parameter is used to store default value of the joint, and nkey=1 to store keyframe with
   default joint positions set !-->
  <size njmax="1000" nconmax="400" nuser_jnt="1" nkey="1"/>
  <worldbody>
    <!-- The converter script assumes a body named 'ground' exists as a child element of worldbody -->
    <body name="ground" euler="1.571 0 0"/>
    <light directional="true"/>
    <body name="pelvis" pos="0 0 0" euler="1.571 0 0">
      <inertial mass="11.1871519306" pos="-0.0707000000 0.0000000000 0.0000000000" fullinertia="0.0976512880 0.0827376185 0.0550000931 0.0000000000 0.0000000000 0.0000000000"/>
      <geom name="pelvis_geom_1" type="mesh" mesh="pelvis_geom_1_r_pelvis" rgba="1 1 1 1" group="0"/>
      <geom name="pelvis_geom_2" type="mesh" mesh="pelvis_geom_2_l_pelvis" rgba="1 1 1 1" group="0"/>
      <geom name="pelvis_geom_3" type="mesh" mesh="pelvis_geom_3_sacrum" rgba="1 1 1 1" group="0"/>
      <geom name="Gmax1_at_pelvis_r_cylinder" type="cylinder" euler="-0.6 0.45 0" pos="-0.07771 -0.09923 0.06796" size="0.04124 0.08001" rgba="0.19 0.83 0.78 0.2" group="2"/>
      <site name="Gmax1_at_pelvis_r_sidesite" pos="-0.1158 -0.08886 0.08313" size="0.0005"/>
      <geom name="Gmax2_at_pelvis_r_cylinder" type="cylinder" euler="-0.75 0.39 0" pos="-0.08074 -0.08319 0.07576" size="0.04146 0.0528" rgba="0.19 0.83 0.78 0.2" group="2"/>
      <geom name="Gmax3_at_pelvis_r_cylinder" type="cylinder" euler="-0.1 0 0" pos="-0.08377 -0.0882 0.07576" size="0.04026 0.05565" rgba="0.19 0.83 0.78 0.2" group="2"/>
      <geom name="Gmax1_at_pelvis_l_cylinder" type="cylinder" euler="0.6 -0.45 0" pos="-0.07771 -0.09923 -0.06796" size="0.04124 0.08001" rgba="0.19 0.83 0.78 0.2" group="2"/>
      <site name="Gmax1_at_pelvis_l_sidesite" pos="-0.1158 -0.08886 -0.08313" size="0.0005"/>
      <geom name="Gmax2_at_pelvis_l_cylinder" type="cylinder" euler="0.75 -0.39 0" pos="-0.08074 -0.08319 -0.07576" size="0.04146 0.0528" rgba="0.19 0.83 0.78 0.2" group="2"/>
      <geom name="Gmax3_at_pelvis_l_cylinder" type="cylinder" euler="0.1 0 0" pos="-0.08377 -0.0882 -0.07576" size="0.04026 0.05565" rgba="0.19 0.83 0.78 0.2" group="2"/>
      <geom name="PS_at_brim_r_cylinder" type="cylinder" euler="-0.25 -0.27 0.1" pos="-0.07468 -0.06014 0.07309" size="0.05065 0.05504" rgba="0.19 0.83 0.78 0.2" group="2"/>
      <site name="PS_at_brim_r_sidesite" pos="-0.06971 -0.1096 0.08713" size="0.0005"/>
      <geom name="PS_at_brim_l_cylinder" type="cylinder" euler="0.25 0.27 0.1" pos="-0.07468 -0.06014 -0.07309" size="0.05065 0.05504" rgba="0.19 0.83 0.78 0.2" group="2"/>
      <site name="PS_at_brim_l_sidesite" pos="-0.06971 -0.1096 -0.08713" size="0.0005"/>
      <geom name="IL_at_brim_r_cylinder" type="cylinder" euler="-0.32 -0.24 0.9" pos="-0.07166 -0.06515 0.08423" size="0.05569 0.05492" rgba="0.19 0.83 0.78 0.2" group="2"/>
      <site name="IL_at_brim_r_sidesite" pos="-0.02852 -0.09528 0.1053" size="0.0005"/>
      <geom name="IL_at_brim_l_cylinder" type="cylinder" euler="0.32 0.24 0.9" pos="-0.07166 -0.06515 -0.08423" size="0.05569 0.05492" rgba="0.19 0.83 0.78 0.2" group="2"/>
      <site name="IL_at_brim_l_sidesite" pos="-0.02852 -0.09528 -0.1053" size="0.0005"/>
      <joint name="pelvis_tx" range="-40 40" limited="true" user="0.0" ref="0" axis="1 0 0" type="slide" damping="0" stiffness="0"/>
      <joint name="pelvis_ty" range="-5 5" limited="true" user="0.93" ref="0" axis="0 1 0" type="slide" damping="0" stiffness="0"/>
      <joint name="pelvis_tz" range="-40 40" limited="true" user="0.0" ref="0" axis="0 0 1" type="slide" damping="0" stiffness="0"/>
      <joint name="pelvis_tilt" range="-3.142 3.142" limited="true" user="0.0" ref="0" axis="0 0 1" type="hinge" damping="0" stiffness="0"/>
      <joint name="pelvis_list" range="-3.142 3.142" limited="true" user="0.0" ref="0" axis="1 0 0" type="hinge" damping="0" stiffness="0"/>
      <joint name="pelvis_rotation" range="-3.142 3.142" limited="true" user="0.0" ref="0" axis="0 1 0" type="hinge" damping="0" stiffness="0"/>
      <body name="femur_r" pos="-0.0568 -0.07867 0.08608" euler="-0 0 0">
        <inertial mass="8.8355417311" pos="0.0000000000 -0.1700000000 0.0000000000" fullinertia="0.1271936523 0.0333420254 0.1341280337 0.0000000000 0.0000000000 0.0000000000"/>
        <geom name="femur_r_geom_1" type="mesh" mesh="femur_r_geom_1_r_femur" rgba="1 1 1 1" group="0"/>
        <geom name="Gastroc_at_condyles_r_cylinder" type="cylinder" euler="0 0 0" pos="0.005722 -0.4761 0" size="0.02882 0.0574" rgba="0.19 0.83 0.78 0.2" group="2"/>
        <geom name="KnExt_at_fem_r_cylinder" type="cylinder" euler="-0.06234 0.05076 0" pos="0.004106 -0.4676 0.002401" size="0.02882 0.05741" rgba="0.19 0.83 0.78 0.2" group="2"/>
        <geom name="AB_at_femshaft_r_cylinder" type="cylinder" euler="1.662 0.1866 0" pos="0.01676 -0.1307 0.02682" size="0.01892 0.04062" rgba="0.19 0.83 0.78 0.2" group="2"/>
        <geom name="AL_at_femshaft_r_cylinder" type="cylinder" euler="1.777 0.1365 0" pos="0.03517 -0.2693 0.01735" size="0.02305 0.05802" rgba="0.19 0.83 0.78 0.2" group="2"/>
        <geom name="AMprox_at_femshaft_r_cylinder" type="cylinder" euler="1.611 0.1866 0" pos="0.005931 -0.08464 0.02916" size="0.02419 0.04062" rgba="0.19 0.83 0.78 0.2" group="2"/>
        <geom name="AMmid_at_femshaft_r_cylinder" type="cylinder" euler="1.611 0.1366 0" pos="0.02634 -0.1866 0.02363" size="0.02453 0.06965" rgba="0.19 0.83 0.78 0.2" group="2"/>
        <geom name="AMdist_at_femshaft_r_cylinder" type="cylinder" euler="1.712 0.1866 0" pos="0.03617 -0.3028 0.01075" size="0.025 0.116" rgba="0.19 0.83 0.78 0.2" group="2"/>
        <geom name="AMisch_at_condyles_r_cylinder" type="cylinder" euler="1.711 -0.4634 0" pos="-0.02592 -0.4376 -0.003621" size="0.04592 0.1389" rgba="0.19 0.83 0.78 0.2" group="2"/>
        <geom name="PECT_at_femshaft_r_cylinder" type="cylinder" euler="1.813 0.2763 0" pos="0.006964 -0.09812 0.03495" size="0.01721 0.02898" rgba="0.19 0.83 0.78 0.2" group="2"/>
        <joint name="hip_flexion_r" range="-0.5236 2.094" limited="true" user="0.0" ref="0" axis="0 0 1" type="hinge"/>
        <joint name="hip_adduction_r" range="-0.8727 0.5236" limited="true" user="0.0" ref="0" axis="1 0 0" type="hinge"/>
        <joint name="hip_rotation_r" range="-0.6981 0.6981" limited="true" user="0.0" ref="0" axis="0 1 0" type="hinge"/>
        <body name="tibia_r" pos="-0.0003256 -0.4696 -0.001516" euler="-2.983e-18 0 -1.649e-18">
          <inertial mass="3.5218107992" pos="0.0000000000 -0.1867000000 0.0000000000" fullinertia="0.0478757287 0.0048445678 0.0485406694 0.0000000000 0.0000000000 0.0000000000"/>
          <geom name="tibia_r_geom_1" type="mesh" mesh="tibia_r_geom_1_r_tibia" rgba="1 1 1 1" group="0"/>
          <geom name="tibia_r_geom_2" type="mesh" mesh="tibia_r_geom_2_r_fibula" rgba="1 1 1 1" group="0"/>
          <geom name="GasLat_at_shank_r_cylinder" type="cylinder" euler="2.967 -0.2797 -1.478" pos="-0.008171 -0.08551 -0.003647" size="0.06211 0.05533" rgba="0.19 0.83 0.78 0.2" group="2"/>
          <site name="GasLat_at_shank_r_sidesite" pos="-0.06857 -0.07674 0.01243" size="0.0005"/>
          <geom name="GasMed_at_shank_r_cylinder" type="cylinder" euler="2.967 0.02797 -1.478" pos="-0.008171 -0.08551 -0.003647" size="0.0621 0.05534" rgba="0.19 0.83 0.78 0.2" group="2"/>
          <site name="GasMed_at_shank_r_sidesite" pos="-0.07098 -0.08006 -0.006391" size="0.0005"/>
          <geom name="GR_at_condyles_r_cylinder" type="cylinder" euler="0 -0.4 0" pos="-0.003313 -0.02311 0" size="0.04068 0.05525" rgba="0.19 0.83 0.78 0.2" group="2"/>
          <geom name="SM_at_condyles_r_cylinder" type="cylinder" euler="0 -0.1 0" pos="-0.001104 -0.02311 0" size="0.03977 0.05526" rgba="0.19 0.83 0.78 0.2" group="2"/>
          <geom name="ST_at_condyles_r_cylinder" type="cylinder" euler="0 -0.2 0" pos="-0.002208 -0.02369 0" size="0.04802 0.05526" rgba="0.19 0.83 0.78 0.2" group="2"/>
          <geom name="BF_at_gastroc_r_cylinder" type="cylinder" euler="0 0 0" pos="-0.06404 -0.06933 0" size="0.0339 0.08289" rgba="0.19 0.83 0.78 0.2" group="2"/>
          <site name="BF_at_gastroc_r_sidesite" pos="-0.06404 -0.03443 0" size="0.0005"/>
          <joint name="walker_knee_r_translation1" range="0 0.001857" limited="true" user="1.1074666082691413e-07" ref="0" axis="-0.1243 0.9898 -0.07016" type="slide"/>
          <joint name="walker_knee_r_translation2" range="0 0.007798" limited="true" user="8.831597606007158e-11" ref="0" axis="0.9922 0.124 -0.008789" type="slide"/>
          <joint name="knee_angle_r" range="0 2.094" limited="true" user="0.0" ref="0" axis="-4.566e-07 -0.07071 -0.9975" type="hinge"/>
          <joint name="walker_knee_r_rotation2" range="-0.001678 0.03354" limited="true" user="-1.4732523270777342e-08" ref="0" axis="0.9922 0.124 -0.008789" type="hinge"/>
          <joint name="walker_knee_r_rotation3" range="0 0.2628" limited="true" user="1.0893911273068824e-08" ref="0" axis="-0.1243 0.9898 -0.07016" type="hinge"/>
          <body name="talus_r" pos="-0.01104 -0.4622 0" euler="-9.828e-18 0 -1.741e-18">
            <inertial mass="0.0949915253" pos="0.0000000000 0.0000000000 0.0000000000" fullinertia="0.0009499153 0.0009499153 0.0009499153 0.0000000000 0.0000000000 0.0000000000"/>
            <geom name="talus_r_geom_1" type="mesh" mesh="talus_r_geom_1_r_talus" rgba="1 1 1 0" group="0"/>
            <joint name="ankle_angle_r" range="-0.6981 0.5236" limited="true" user="0.0" ref="0" type="hinge" axis="-0.105 -0.174 0.9791"/>
            <body name="calcn_r" pos="-0.05632 -0.04962 0.009263" euler="-5.48e-17 0 -2.48e-17">
              <inertial mass="1.1873940658" pos="0.1000000000 0.0300000000 0.0000000000" fullinertia="0.0013298814 0.0037046695 0.0038946525 0.0000000000 0.0000000000 0.0000000000"/>
              <geom name="calcn_r_geom_1" type="mesh" mesh="calcn_r_geom_1_r_foot" rgba="1 1 1 1" group="0"/>
              <joint name="subtalar_angle_r" range="-0.3491 0.3491" limited="true" user="0.0" ref="0" type="hinge" axis="0.7872 0.6047 -0.1209"/>
              <body name="toes_r" pos="0.1909 -0.002105 0.001153" euler="-8.855e-23 0 2.177e-23">
                <inertial mass="0.2057516437" pos="0.0346000000 0.0060000000 -0.0175000000" fullinertia="0.0005989216 0.0006939131 0.0009499153 0.0000000000 0.0000000000 0.0000000000"/>
                <geom name="toes_r_geom_1" type="mesh" mesh="toes_r_geom_1_r_bofoot" rgba="1 1 1 1" group="0"/>
                <joint name="mtp_angle_r" range="-0.5236 0.5236" limited="true" user="0.0" ref="0" type="hinge" axis="0.581 2.16e-06 -0.8139"/>
                <site name="edl_r_edl_r-P5" pos="0.00033533783942999996 0.0052532985319300009 0.017103254927759999"/>
                <site name="edl_r_edl_r-P6" pos="0.04951822095583 -0.00044708923676000008 0.02794649498"/>
                <site name="ehl_r_ehl_r-P7" pos="0.03331022538338 0.004582664676790001 -0.027387565080399998"/>
                <site name="ehl_r_ehl_r-P8" pos="0.062931734533029998 0.0038002585124600002 -0.020792192265119996"/>
                <site name="fdl_r_fdl_r-P6" pos="-0.0021238063163899999 -0.0087182401168200002 0.016432539048239998"/>
                <site name="fdl_r_fdl_r-P7" pos="0.031857094745850002 -0.0079358339524900016 0.024033985682799994"/>
                <site name="fdl_r_fdl_r-P8" pos="0.049294662396209998 -0.0067063385514000004 0.027052207140639998"/>
                <site name="fhl_r_fhl_r-P6" pos="0.017325788370549999 -0.0071534277881600012 -0.029623284678799995"/>
                <site name="fhl_r_fhl_r-P7" pos="0.062819955253219997 -0.011400775537380002 -0.020233262365519998"/>
              </body>
              <site name="edl_r_edl_r-P3" pos="0.098134081319630001 0.037888819480799994 0.00085421345056000005"/>
              <site name="edl_r_edl_r-P4" pos="0.17256221481232001 0.0057885696428999992 0.013880968571599999"/>
              <site name="ehl_r_ehl_r-P4" pos="0.1035800423069 0.040940974383419995 -0.022529879758519999"/>
              <site name="ehl_r_ehl_r-P5" pos="0.13807112855961001 0.032521236721019996 -0.027441607099240001"/>
              <site name="ehl_r_ehl_r-P6" pos="0.18516267356718 0.014629294188419998 -0.029897470769600001"/>
              <site name="fdl_r_fdl_r-P3" pos="0.046557627263720001 0.033152717045699998 -0.029897470769600001"/>
              <site name="fdl_r_fdl_r-P4" pos="0.075602752529160003 0.018523422857279998 -0.02808226718716"/>
              <site name="fdl_r_fdl_r-P5" pos="0.17704712386066002 -0.0085249843831799992 0.01238609503312"/>
              <site name="fhl_r_fhl_r-P3" pos="0.039937047239980004 0.029048094935279996 -0.025733180198120001"/>
              <site name="fhl_r_fhl_r-P4" pos="0.11084132362326 0.0071567770130399992 -0.027334830417920002"/>
              <site name="fhl_r_fhl_r-P5" pos="0.18430840517702002 -0.0055780762013399997 -0.028722927275079999"/>
              <site name="gaslat_r_gaslat_r-P2" pos="0.0046984761458800008 0.032626483441799997 -0.0056591641099599998"/>
              <site name="gasmed_r_gasmed_r-P2" pos="0.0046984761458800008 0.032626483441799997 -0.0056591641099599998"/>
              <site name="perbrev_r_perbrev_r-P4" pos="0.050295051470670003 0.028416614610599997 0.024878966747560002"/>
              <site name="perbrev_r_perbrev_r-P5" pos="0.072292462517290004 0.023049031850819999 0.036624401692759996"/>
              <site name="perlong_r_perlong_r-P4" pos="0.046771194361260003 0.024206745779399998 0.023597646571720001"/>
              <site name="perlong_r_perlong_r-P5" pos="0.072719596712369994 0.011156152402679999 0.03032457749488"/>
              <site name="perlong_r_perlong_r-P6" pos="0.09097958355204 0.007262023733819999 0.012599648395759999"/>
              <site name="perlong_r_perlong_r-P7" pos="0.12846060917031002 0.0089459712662999999 -0.019646909362880001"/>
              <site name="soleus_r_soleus_r-P2" pos="0.0046984761458800008 0.032626483441799997 -0.0056591641099599998"/>
              <site name="tibant_r_tibant_r-P4" pos="0.12450961786582 0.018733916298839998 -0.032566887802599996"/>
              <site name="tibpost_r_tibpost_r-P3" pos="0.044528739837089999 0.035152404740519998 -0.03053813085752"/>
              <site name="tibpost_r_tibpost_r-P4" pos="0.082436899650440001 0.016734228604020001 -0.030004247450920001"/>
            </body>
          </body>
          <site name="bflh_r_bflh_r-P2" pos="-0.037211975818510004 -0.040442048993500006 0.027960995260989999"/>
          <site name="bflh_r_bflh_r-P3" pos="-0.031690911157010004 -0.052574663691549998 0.033486883652490002"/>
          <site name="bfsh_r_bfsh_r-P2" pos="-0.033236809262230001 -0.048414910080789998 0.035144650169940006"/>
          <site name="edl_r_edl_r-P1" pos="-0.017667406916800001 -0.13368985910136999 0.022656142405150001"/>
          <site name="edl_r_edl_r-P2" pos="0.018109092089720003 -0.43446315490160003 0.01237798999696"/>
          <site name="ehl_r_ehl_r-P1" pos="-0.015458981052200001 -0.17910050268550001 0.020887858119870002"/>
          <site name="ehl_r_ehl_r-P2" pos="0.0078399118193300012 -0.33613120149169001 0.018124913924120002"/>
          <site name="ehl_r_ehl_r-P3" pos="0.022084258646000002 -0.42672139123713004 -0.0030944974992399999"/>
          <site name="fdl_r_fdl_r-P1" pos="-0.0025396897442900002 -0.21168523930312 -0.0019893198209399998"/>
          <site name="fdl_r_fdl_r-P2" pos="-0.019434147608480001 -0.42117505308945002 -0.01370420321092"/>
          <site name="fhl_r_fhl_r-P1" pos="-0.0342306009013 -0.24993186277983001 0.022103553566000002"/>
          <site name="fhl_r_fhl_r-P2" pos="-0.026721952961660002 -0.42417931958610999 -0.00839935035508"/>
          <site name="grac_r_grac_r-P2" pos="-0.020339602212966001 -0.054943412275455003 -0.032724311054463003"/>
          <site name="grac_r_grac_r-P3" pos="0.0019654990194940001 -0.080445012883642003 -0.017384444879659001"/>
          <site name="GR_at_condyles_r_cylinder_grac_r_1_sidesite" pos="-0.01704 -0.002322 -0.03544" size="0.0005"/>
          <site name="perbrev_r_perbrev_r-P1" pos="-0.026832374254890001 -0.29256933729011997 0.027739959725330002"/>
          <site name="perbrev_r_perbrev_r-P2" pos="-0.037432818404970002 -0.44983113351913001 0.027518924189669999"/>
          <site name="perbrev_r_perbrev_r-P3" pos="-0.03147006857055 -0.46265704048563999 0.02818203079665"/>
          <site name="perlong_r_perlong_r-P1" pos="-0.022084258646000002 -0.15864838076593002 0.031166010528059999"/>
          <site name="perlong_r_perlong_r-P2" pos="-0.035003549953910001 -0.45063997449900001 0.02619271097571"/>
          <site name="perlong_r_perlong_r-P3" pos="-0.030034591758559999 -0.46381252759974001 0.026524264279200002"/>
          <site name="recfem_r_recfem_r-P5" pos="0.035997341592980001 -0.072934346641991998 -0.00051943350880099995"/>
          <site name="sart_r_sart_r-P3" pos="-0.027715744600730001 -0.046335033275409998 -0.040338985257949996"/>
          <site name="sart_r_sart_r-P4" pos="-0.017556985623570002 -0.069213678134590007 -0.02917669070712"/>
          <site name="sart_r_sart_r-P5" pos="0.015017295879279999 -0.093594456242100013 -0.00287346196358"/>
          <site name="semimem_r_semimem_r-P2" pos="-0.032022175036700004 -0.048183812657970004 -0.021661482494680001"/>
          <site name="SM_at_condyles_r_cylinder_semimem_r_1_sidesite" pos="-0.03202 -0.04818 -0.02166" size="0.0005"/>
          <site name="semiten_r_semiten_r-P2" pos="-0.034451443487759997 -0.058698745396279998 -0.025308568833070002"/>
          <site name="semiten_r_semiten_r-P3" pos="0.00209800457137 -0.089319153919929992 -0.012930578836110001"/>
          <site name="ST_at_condyles_r_cylinder_semiten_r_1_sidesite" pos="-0.03802 -0.004059 -0.02711" size="0.0005"/>
          <site name="soleus_r_soleus_r-P1" pos="-0.0083920182854800001 -0.10584261965156 0.010830741247340001"/>
          <site name="tfl_r_tfl_r-P4" pos="0.011925499668840002 -0.047374971678100002 0.038239147669179997"/>
          <site name="tibant_r_tibant_r-P1" pos="0.017004879157420001 -0.15159990936992002 0.017903878388459998"/>
          <site name="tibant_r_tibant_r-P2" pos="0.027715744600730001 -0.22023584394745999 0.014146274282240001"/>
          <site name="tibant_r_tibant_r-P3" pos="0.025728161322590003 -0.42279273504919002 -0.01458834535356"/>
          <site name="tibpost_r_tibpost_r-P1" pos="-0.0045272730224300006 -0.15067551967863999 0.01138333008649"/>
          <site name="tibpost_r_tibpost_r-P2" pos="-0.018109092089720003 -0.42233054020354999 -0.019340609370250002"/>
          <site name="vasint_r_vasint_r-P5" pos="0.035964215205011002 -0.073026785611120013 0.00047522640166900002"/>
          <site name="vaslat_r_vaslat_r-P5" pos="0.035931088817042003 -0.073234773291658006 0.0056474579361130003"/>
          <site name="vasmed_r_vasmed_r-P5" pos="0.035224392540369999 -0.073454315843337004 -0.0074931046588740001"/>
        </body>
        <body name="patella_r" pos="-0.009258 -0.4737 -0.003157" euler="-0 0 0">
          <inertial mass="0.063731339850426574" pos="0.0018 0.0264 0" fullinertia="2.1219135193819521e-06 9.6927826617064097e-06 9.6927826617064097e-06 0 0 0"/>
          <geom name="patella_r_geom_1" type="mesh" mesh="patella_r_geom_1_r_patella" rgba="1 1 1 1" group="0"/>
          <joint name="patellofemoral_r_translation1" range="-0.02598 0.05997" limited="true" user="0.05998822768435878" ref="0" axis="1 0 0" type="slide"/>
          <joint name="patellofemoral_r_translation2" range="-0.04738 -0.01254" limited="true" user="-0.012573525423024118" ref="0" axis="0 1 0" type="slide"/>
          <joint name="patellofemoral_r_translation3" limited="false" ref="0" axis="0 0 1" type="slide"/>
          <joint name="patellofemoral_r_rotation1" range="-1.786 0.001137" limited="true" user="0.010505984997239537" ref="0" axis="0 0 1" type="hinge"/>
          <site name="recfem_r_recfem_r-P2" pos="0.01 0.049000000000000002 0.00069999999999999999"/>
          <site name="recfem_r_recfem_r-P3" pos="0.0121 0.043700000000000003 -0.001"/>
          <site name="recfem_r_recfem_r-P4" pos="0.0050000000000000001 0.00247 3.0000000000000001e-05"/>
          <site name="vasint_r_vasint_r-P3" pos="0.0057999999999999996 0.048000000000000001 -0.00059999999999999995"/>
          <site name="vasint_r_vasint_r-P4" pos="0.0050000000000000001 0.00247 -0.00038999999999999999"/>
          <site name="vaslat_r_vaslat_r-P3" pos="0.0103 0.042299999999999997 0.0141"/>
          <site name="vaslat_r_vaslat_r-P4" pos="0.0050000000000000001 0.00247 0.0073299999999999997"/>
          <site name="vasmed_r_vasmed_r-P3" pos="0.0063 0.044499999999999998 -0.017000000000000001"/>
          <site name="vasmed_r_vasmed_r-P4" pos="0.0050000000000000001 0.00247 -0.0085000000000000006"/>
        </body>
        <site name="addbrev_r_addbrev_r-P2" pos="-0.0022887870224000003 -0.1370205325012 0.028587011016839997"/>
        <site name="AB_at_femshaft_r_cylinder_addbrev_r_1_sidesite" pos="0.001134 -0.123 0.01713" size="0.0005"/>
        <site name="addlong_r_addlong_r-P2" pos="0.012885870936112001 -0.27795427851535798 0.018173991341227998"/>
        <site name="AL_at_femshaft_r_cylinder_addlong_r_1_sidesite" pos="0.01289 -0.278 0.01817" size="0.0005"/>
        <site name="addmagDist_r_addmagDist_r-P2" pos="0.012874427001000001 -0.30481262526750003 0.02215780371988"/>
        <site name="AMdist_at_femshaft_r_cylinder_addmagDist_r_1_sidesite" pos="0.01287 -0.3048 0.02216" size="0.0005"/>
        <site name="addmagIsch_r_addmagIsch_r-P2" pos="0.0055045327888720002 -0.45050725419059801 -0.037576420505268"/>
        <site name="AMisch_at_condyles_r_cylinder_addmagIsch_r_1_sidesite" pos="0.005505 -0.4505 -0.03758" size="0.0005"/>
        <site name="addmagMid_r_addmagMid_r-P2" pos="0.0027694322971039999 -0.18857741083215998 0.033546685217351997"/>
        <site name="AMmid_at_femshaft_r_cylinder_addmagMid_r_1_sidesite" pos="0.002769 -0.1886 0.03355" size="0.0005"/>
        <site name="addmagProx_r_addmagProx_r-P2" pos="-0.017474888916024001 -0.091571518585123995 0.036761288865831999"/>
        <site name="AMprox_at_femshaft_r_cylinder_addmagProx_r_1_sidesite" pos="-0.0186 -0.08463 0.02342" size="0.0005"/>
        <site name="bfsh_r_bfsh_r-P1" pos="0.0057219675560000009 -0.24512741026274001 0.02686490191944"/>
        <site name="gaslat_r_gaslat_r-P1" pos="-0.0034331805336000002 -0.44287822962676004 0.031801614665319992"/>
        <site name="Gastroc_at_condyles_r_cylinder_gaslat_r_1_sidesite" pos="-0.01005 -0.4991 0.0285" size="0.0005"/>
        <site name="gasmed_r_gasmed_r-P1" pos="0.0091551480896000011 -0.43985913314792002 -0.023879912817279997"/>
        <site name="Gastroc_at_condyles_r_cylinder_gasmed_r_1_sidesite" pos="0.001139 -0.4964 -0.02099" size="0.0005"/>
        <site name="glmax1_r_glmax1_r-P3" pos="-0.050811071897280007 -0.037854825080839996 0.034671796494319999"/>
        <site name="glmax1_r_glmax1_r-P4" pos="-0.03169970026024 -0.06572340796244 0.053959418385199992"/>
        <site name="glmax2_r_glmax2_r-P3" pos="-0.051497708004000005 -0.06781355167856 0.028931432836319996"/>
        <site name="glmax2_r_glmax2_r-P4" pos="-0.017852538774720001 -0.11797700086544 0.048104247454039996"/>
        <site name="glmax3_r_glmax3_r-P3" pos="-0.032157457664720002 -0.1306339822575 0.010791883677039999"/>
        <site name="glmax3_r_glmax3_r-P4" pos="-0.0068663610672000004 -0.16477299628746001 0.047185789268759992"/>
        <site name="glmed1_r_glmed1_r-P2_0" pos="-0.015897633956418768 -0.021243646094053763 0.067953988391736025"/>
        <site name="glmed2_r_glmed2_r-P2_0" pos="-0.025217871750009113 -0.011564413338224978 0.064436986864732454"/>
        <site name="glmed3_r_glmed3_r-P2_0" pos="-0.035361759496080003 -0.0054575974809800004 0.059470167496879993"/>
        <site name="glmin1_r_glmin1_r-P2" pos="0.0062819407906364449 -0.017985223483758365 0.064335473233078366"/>
        <site name="glmin2_r_glmin2_r-P2" pos="0.004055205247408069 -0.010464965200667316 0.060232864024400604"/>
        <site name="glmin3_r_glmin3_r-P2" pos="-0.0040925083640575115 -0.0014708814734542717 0.058852102000240304"/>
        <site name="iliacus_r_iliacus_r-P3" pos="-0.0026321050757600003 -0.065607288867100003 0.015958210969239998"/>
        <site name="iliacus_r_iliacus_r-P4" pos="-0.013961600836640001 -0.073967863731580014 0.022502225539359998"/>
        <site name="piri_r_piri_r-P3" pos="-0.016937023965760002 -0.0041802874322400003 0.050170778370919995"/>
        <site name="psoas_r_psoas_r-P3" pos="-0.015105994347840001 -0.054227617523779997 0.0052811345653599991"/>
        <site name="psoas_r_psoas_r-P4" pos="-0.026893247513200002 -0.060846405958160002 0.01010304003808"/>
        <site name="KnExt_at_fem_r_cylinder_recfem_r_3_sidesite" pos="-0.01969 -0.4646 -0.01532" size="0.0005"/>
        <site name="KnExt_at_fem_r_cylinder_recfem_r_2_sidesite" pos="0.002842 -0.43 -0.004157" size="0.0005"/>
        <site name="sart_r_sart_r-P2" pos="-0.0034331805336000002 -0.41431293217311999 -0.048333862000359995"/>
        <site name="tfl_r_tfl_r-P2" pos="0.03364516922928 -0.1155384998633 0.068539942076519991"/>
        <site name="tfl_r_tfl_r-P3" pos="0.01224501056984 -0.47028233612700004 0.037197556503839997"/>
        <site name="vasint_r_vasint_r-P1" pos="0.033187411824800006 -0.22341313943416 0.035590254679599996"/>
        <site name="vasint_r_vasint_r-P2" pos="0.038337182625200007 -0.24199219468856001 0.032720072850599996"/>
        <site name="KnExt_at_fem_r_cylinder_vasint_r_3_sidesite" pos="-0.01984 -0.4635 -0.01488" size="0.0005"/>
        <site name="KnExt_at_fem_r_cylinder_vasint_r_2_sidesite" pos="-0.003458 -0.4257 -0.003757" size="0.0005"/>
        <site name="vaslat_r_vaslat_r-P1" pos="0.0054930888537600003 -0.21528480276036002 0.040067738332839997"/>
        <site name="vaslat_r_vaslat_r-P2" pos="0.030784185451280002 -0.30086457602594002 0.046956174722439993"/>
        <site name="KnExt_at_fem_r_cylinder_vaslat_r_3_sidesite" pos="-0.02412 -0.4647 0.01157" size="0.0005"/>
        <site name="KnExt_at_fem_r_cylinder_vaslat_r_2_sidesite" pos="0.001042 -0.4314 0.01094" size="0.0005"/>
        <site name="vasmed_r_vasmed_r-P1" pos="0.016021509156800003 -0.24373398111866001 0.021583767354079998"/>
        <site name="vasmed_r_vasmed_r-P2" pos="0.040740408998720001 -0.32153377499645996 0.0010332654584399999"/>
        <site name="KnExt_at_fem_r_cylinder_vasmed_r_4_sidesite" pos="-0.01078 -0.4741 -0.02262" size="0.0005"/>
        <site name="KnExt_at_fem_r_cylinder_vasmed_r_3_sidesite" pos="-0.01078 -0.4741 -0.02262" size="0.0005"/>
      </body>
      <body name="femur_l" pos="-0.0568 -0.07867 -0.08608" euler="-0 0 0">
        <inertial mass="8.8355417311" pos="0.0000000000 -0.1700000000 0.0000000000" fullinertia="0.1271936523 0.0333420254 0.1341280337 0.0000000000 0.0000000000 0.0000000000"/>
        <geom name="femur_l_geom_1" type="mesh" mesh="femur_l_geom_1_l_femur" rgba="1 1 1 1" group="0"/>
        <geom name="Gastroc_at_condyles_l_cylinder" type="cylinder" euler="0 0 0" pos="0.005722 -0.4761 0" size="0.02882 0.0574" rgba="0.19 0.83 0.78 0.2" group="2"/>
        <geom name="KnExt_at_fem_l_cylinder" type="cylinder" euler="0.06234 -0.05076 0" pos="0.004106 -0.4676 -0.002401" size="0.02882 0.05741" rgba="0.19 0.83 0.78 0.2" group="2"/>
        <geom name="AB_at_femshaft_l_cylinder" type="cylinder" euler="-1.662 -0.1866 0" pos="0.01676 -0.1307 -0.02682" size="0.01892 0.04062" rgba="0.19 0.83 0.78 0.2" group="2"/>
        <geom name="AL_at_femshaft_l_cylinder" type="cylinder" euler="-1.777 -0.1365 0" pos="0.03517 -0.2693 -0.01735" size="0.02305 0.05802" rgba="0.19 0.83 0.78 0.2" group="2"/>
        <geom name="AMprox_at_femshaft_l_cylinder" type="cylinder" euler="-1.611 -0.1866 0" pos="0.005931 -0.08464 -0.02916" size="0.02419 0.04062" rgba="0.19 0.83 0.78 0.2" group="2"/>
        <geom name="AMmid_at_femshaft_l_cylinder" type="cylinder" euler="-1.611 -0.1366 0" pos="0.02634 -0.1866 -0.02363" size="0.02453 0.06965" rgba="0.19 0.83 0.78 0.2" group="2"/>
        <geom name="AMdist_at_femshaft_l_cylinder" type="cylinder" euler="-1.712 -0.1866 0" pos="0.03617 -0.3028 -0.01075" size="0.025 0.116" rgba="0.19 0.83 0.78 0.2" group="2"/>
        <geom name="AMisch_at_condyles_l_cylinder" type="cylinder" euler="-1.711 0.4634 0" pos="-0.02592 -0.4376 0.003621" size="0.04592 0.1389" rgba="0.19 0.83 0.78 0.2" group="2"/>
        <geom name="PECT_at_femshaft_l_cylinder" type="cylinder" euler="-1.813 -0.2763 0" pos="0.006964 -0.09812 -0.03495" size="0.01721 0.02898" rgba="0.19 0.83 0.78 0.2" group="2"/>
        <joint name="hip_flexion_l" range="-0.5236 2.094" limited="true" user="0.0" ref="0" axis="0 0 1" type="hinge"/>
        <joint name="hip_adduction_l" range="-0.8727 0.5236" limited="true" user="-0.0" ref="0" axis="-1 -0 -0" type="hinge"/>
        <joint name="hip_rotation_l" range="-0.6981 0.6981" limited="true" user="-0.0" ref="0" axis="-0 -1 -0" type="hinge"/>
        <body name="tibia_l" pos="-0.0003256 -0.4696 0.001516" euler="2.983e-18 0 -1.649e-18">
          <inertial mass="3.5218107992" pos="0.0000000000 -0.1867000000 0.0000000000" fullinertia="0.0478757287 0.0048445678 0.0485406694 0.0000000000 0.0000000000 0.0000000000"/>
          <geom name="tibia_l_geom_1" type="mesh" mesh="tibia_l_geom_1_l_tibia" rgba="1 1 1 1" group="0"/>
          <geom name="tibia_l_geom_2" type="mesh" mesh="tibia_l_geom_2_l_fibula" rgba="1 1 1 1" group="0"/>
          <geom name="GasLat_at_shank_l_cylinder" type="cylinder" euler="-2.967 0.2797 -1.478" pos="-0.008171 -0.08551 0.003647" size="0.06211 0.05533" rgba="0.19 0.83 0.78 0.2" group="2"/>
          <site name="GasLat_at_shank_l_sidesite" pos="-0.06857 -0.07674 -0.01243" size="0.0005"/>
          <geom name="GasMed_at_shank_l_cylinder" type="cylinder" euler="-2.967 -0.02797 -1.478" pos="-0.008171 -0.08551 0.003647" size="0.0621 0.05534" rgba="0.19 0.83 0.78 0.2" group="2"/>
          <site name="GasMed_at_shank_l_sidesite" pos="-0.07098 -0.08006 0.006391" size="0.0005"/>
          <geom name="GR_at_condyles_l_cylinder" type="cylinder" euler="0 0.4 0" pos="-0.003313 -0.02311 0" size="0.04068 0.05525" rgba="0.19 0.83 0.78 0.2" group="2"/>
          <geom name="SM_at_condyles_l_cylinder" type="cylinder" euler="0 0.1 0" pos="-0.001104 -0.02311 0" size="0.03977 0.05526" rgba="0.19 0.83 0.78 0.2" group="2"/>
          <geom name="ST_at_condyles_l_cylinder" type="cylinder" euler="0 0.2 0" pos="-0.002208 -0.02369 0" size="0.04802 0.05526" rgba="0.19 0.83 0.78 0.2" group="2"/>
          <geom name="BF_at_gastroc_l_cylinder" type="cylinder" euler="0 0 0" pos="-0.06404 -0.06933 0" size="0.0339 0.08289" rgba="0.19 0.83 0.78 0.2" group="2"/>
          <joint name="walker_knee_l_translation1" range="0 0.001857" limited="true" user="1.1074666082691413e-07" ref="0" axis="-0.1243 0.9898 0.07016" type="slide"/>
          <joint name="walker_knee_l_translation2" range="-0.007798 0" limited="true" user="-8.831597606007158e-11" ref="0" axis="-0.9922 -0.124 -0.008789" type="slide"/>
          <joint name="knee_angle_l" range="0 2.094" limited="true" user="0.0" ref="0" axis="4.566e-07 0.07071 -0.9975" type="hinge"/>
          <joint name="walker_knee_l_rotation2" range="-0.001678 0.03354" limited="true" user="-1.4732523270777342e-08" ref="0" axis="-0.9922 -0.124 -0.008789" type="hinge"/>
          <joint name="walker_knee_l_rotation3" range="-0.2628 0" limited="true" user="-1.0893911273068824e-08" ref="0" axis="-0.1243 0.9898 0.07016" type="hinge"/>
          <body name="talus_l" pos="-0.01104 -0.4622 0" euler="9.828e-18 0 -1.741e-18">
            <inertial mass="0.0949915253" pos="0.0000000000 0.0000000000 0.0000000000" fullinertia="0.0009499153 0.0009499153 0.0009499153 0.0000000000 0.0000000000 0.0000000000"/>
            <geom name="talus_l_geom_1" type="mesh" mesh="talus_l_geom_1_l_talus" rgba="1 1 1 0" group="0"/>
            <joint name="ankle_angle_l" range="-0.6981 0.5236" limited="true" user="0.0" ref="0" type="hinge" axis="0.105 0.174 0.9791"/>
            <body name="calcn_l" pos="-0.05632 -0.04962 -0.009263" euler="5.48e-17 0 -2.48e-17">
              <inertial mass="1.1873940658" pos="0.1000000000 0.0300000000 0.0000000000" fullinertia="0.0013298814 0.0037046695 0.0038946525 0.0000000000 0.0000000000 0.0000000000"/>
              <geom name="calcn_l_geom_1" type="mesh" mesh="calcn_l_geom_1_l_foot" rgba="1 1 1 1" group="0"/>
              <joint name="subtalar_angle_l" range="-0.3491 0.3491" limited="true" user="0.0" ref="0" type="hinge" axis="-0.7872 -0.6047 -0.1209"/>
              <body name="toes_l" pos="0.1909 -0.002105 -0.001153" euler="-8.855e-23 0 -2.177e-23">
                <inertial mass="0.2057516437" pos="0.0346000000 0.0060000000 0.0175000000" fullinertia="0.0005989216 0.0006939131 0.0009499153 0.0000000000 0.0000000000 0.0000000000"/>
                <geom name="toes_l_geom_1" type="mesh" mesh="toes_l_geom_1_l_bofoot" rgba="1 1 1 1" group="0"/>
                <joint name="mtp_angle_l" range="-0.5236 0.5236" limited="true" user="0.0" ref="0" type="hinge" axis="-0.581 2.16e-06 -0.8139"/>
                <site name="edl_l_edl_l-P5" pos="0.00033533783942999996 0.0052532985319300009 -0.017103254927759999"/>
                <site name="edl_l_edl_l-P6" pos="0.04951822095583 -0.00044708923676000008 -0.02794649498"/>
                <site name="ehl_l_ehl_l-P7" pos="0.03331022538338 0.004582664676790001 0.027387565080399998"/>
                <site name="ehl_l_ehl_l-P8" pos="0.062931734533029998 0.0038002585124600002 0.020792192265119996"/>
                <site name="fdl_l_fdl_l-P6" pos="-0.0021238063163899999 -0.0087182401168200002 -0.016432539048239998"/>
                <site name="fdl_l_fdl_l-P7" pos="0.031857094745850002 -0.0079358339524900016 -0.024033985682799994"/>
                <site name="fdl_l_fdl_l-P8" pos="0.049294662396209998 -0.0067063385514000004 -0.027052207140639998"/>
                <site name="fhl_l_fhl_l-P6" pos="0.017325788370549999 -0.0071534277881600012 0.029623284678799995"/>
                <site name="fhl_l_fhl_l-P7" pos="0.062819955253219997 -0.011400775537380002 0.020233262365519998"/>
              </body>
              <site name="edl_l_edl_l-P3" pos="0.098134081319630001 0.037888819480799994 -0.00085421345056000005"/>
              <site name="edl_l_edl_l-P4" pos="0.17256221481232001 0.0057885696428999992 -0.013880968571599999"/>
              <site name="ehl_l_ehl_l-P4" pos="0.1035800423069 0.040940974383419995 0.022529879758519999"/>
              <site name="ehl_l_ehl_l-P5" pos="0.13807112855961001 0.032521236721019996 0.027441607099240001"/>
              <site name="ehl_l_ehl_l-P6" pos="0.18516267356718 0.014629294188419998 0.029897470769600001"/>
              <site name="fdl_l_fdl_l-P3" pos="0.046557627263720001 0.033152717045699998 0.029897470769600001"/>
              <site name="fdl_l_fdl_l-P4" pos="0.075602752529160003 0.018523422857279998 0.02808226718716"/>
              <site name="fdl_l_fdl_l-P5" pos="0.17704712386066002 -0.0085249843831799992 -0.01238609503312"/>
              <site name="fhl_l_fhl_l-P3" pos="0.039937047239980004 0.029048094935279996 0.025733180198120001"/>
              <site name="fhl_l_fhl_l-P4" pos="0.11084132362326 0.0071567770130399992 0.027334830417920002"/>
              <site name="fhl_l_fhl_l-P5" pos="0.18430840517702002 -0.0055780762013399997 0.028722927275079999"/>
              <site name="gaslat_l_gaslat_l-P2" pos="0.0046984761458800008 0.032626483441799997 0.0056591641099599998"/>
              <site name="gasmed_l_gasmed_l-P2" pos="0.0046984761458800008 0.032626483441799997 0.0056591641099599998"/>
              <site name="perbrev_l_perbrev_l-P4" pos="0.050295051470670003 0.028416614610599997 -0.024878966747560002"/>
              <site name="perbrev_l_perbrev_l-P5" pos="0.072292462517290004 0.023049031850819999 -0.036624401692759996"/>
              <site name="perlong_l_perlong_l-P4" pos="0.046771194361260003 0.024206745779399998 -0.023597646571720001"/>
              <site name="perlong_l_perlong_l-P5" pos="0.072719596712369994 0.011156152402679999 -0.03032457749488"/>
              <site name="perlong_l_perlong_l-P6" pos="0.09097958355204 0.007262023733819999 -0.012599648395759999"/>
              <site name="perlong_l_perlong_l-P7" pos="0.12846060917031002 0.0089459712662999999 0.019646909362880001"/>
              <site name="soleus_l_soleus_l-P2" pos="0.0046984761458800008 0.032626483441799997 0.0056591641099599998"/>
              <site name="tibant_l_tibant_l-P4" pos="0.12450961786582 0.018733916298839998 0.032566887802599996"/>
              <site name="tibpost_l_tibpost_l-P3" pos="0.044528739837089999 0.035152404740519998 0.03053813085752"/>
              <site name="tibpost_l_tibpost_l-P4" pos="0.082436899650440001 0.016734228604020001 0.030004247450920001"/>
            </body>
          </body>
          <site name="bflh_l_bflh_l-P2" pos="-0.037211975818510004 -0.040442048993500006 -0.027960995260989999"/>
          <site name="bflh_l_bflh_l-P3" pos="-0.031690911157010004 -0.052574663691549998 -0.033486883652490002"/>
          <site name="bfsh_l_bfsh_l-P2" pos="-0.033236809262230001 -0.048414910080789998 -0.035144650169940006"/>
          <site name="edl_l_edl_l-P1" pos="-0.017667406916800001 -0.13368985910136999 -0.022656142405150001"/>
          <site name="edl_l_edl_l-P2" pos="0.018109092089720003 -0.43446315490160003 -0.01237798999696"/>
          <site name="ehl_l_ehl_l-P1" pos="-0.015458981052200001 -0.17910050268550001 -0.020887858119870002"/>
          <site name="ehl_l_ehl_l-P2" pos="0.0078399118193300012 -0.33613120149169001 -0.018124913924120002"/>
          <site name="ehl_l_ehl_l-P3" pos="0.022084258646000002 -0.42672139123713004 0.0030944974992399999"/>
          <site name="fdl_l_fdl_l-P1" pos="-0.0025396897442900002 -0.21168523930312 0.0019893198209399998"/>
          <site name="fdl_l_fdl_l-P2" pos="-0.019434147608480001 -0.42117505308945002 0.01370420321092"/>
          <site name="fhl_l_fhl_l-P1" pos="-0.0342306009013 -0.24993186277983001 -0.022103553566000002"/>
          <site name="fhl_l_fhl_l-P2" pos="-0.026721952961660002 -0.42417931958610999 0.00839935035508"/>
          <site name="grac_l_grac_l-P2" pos="-0.020339602212966001 -0.054943412275455003 0.032724311054463003"/>
          <site name="grac_l_grac_l-P3" pos="0.0019654990194940001 -0.080445012883642003 0.017384444879659001"/>
          <site name="GR_at_condyles_l_cylinder_grac_l_1_sidesite" pos="-0.01704 -0.002322 0.03544" size="0.0005"/>
          <site name="perbrev_l_perbrev_l-P1" pos="-0.026832374254890001 -0.29256933729011997 -0.027739959725330002"/>
          <site name="perbrev_l_perbrev_l-P2" pos="-0.037432818404970002 -0.44983113351913001 -0.027518924189669999"/>
          <site name="perbrev_l_perbrev_l-P3" pos="-0.03147006857055 -0.46265704048563999 -0.02818203079665"/>
          <site name="perlong_l_perlong_l-P1" pos="-0.022084258646000002 -0.15864838076593002 -0.031166010528059999"/>
          <site name="perlong_l_perlong_l-P2" pos="-0.035003549953910001 -0.45063997449900001 -0.02619271097571"/>
          <site name="perlong_l_perlong_l-P3" pos="-0.030034591758559999 -0.46381252759974001 -0.026524264279200002"/>
          <site name="recfem_l_recfem_l-P5" pos="0.035997341592980001 -0.072934346641991998 0.00051943350880099995"/>
          <site name="sart_l_sart_l-P3" pos="-0.027715744600730001 -0.046335033275409998 0.040338985257949996"/>
          <site name="sart_l_sart_l-P4" pos="-0.017556985623570002 -0.069213678134590007 0.02917669070712"/>
          <site name="sart_l_sart_l-P5" pos="0.015017295879279999 -0.093594456242100013 0.00287346196358"/>
          <site name="semimem_l_semimem_l-P2" pos="-0.032022175036700004 -0.048183812657970004 0.021661482494680001"/>
          <site name="SM_at_condyles_l_cylinder_semimem_l_1_sidesite" pos="-0.03202 -0.04818 0.02166" size="0.0005"/>
          <site name="semiten_l_semiten_l-P2" pos="-0.034451443487759997 -0.058698745396279998 0.025308568833070002"/>
          <site name="semiten_l_semiten_l-P3" pos="0.00209800457137 -0.089319153919929992 0.012930578836110001"/>
          <site name="ST_at_condyles_l_cylinder_semiten_l_1_sidesite" pos="-0.03802 -0.004059 0.02711" size="0.0005"/>
          <site name="soleus_l_soleus_l-P1" pos="-0.0083920182854800001 -0.10584261965156 -0.010830741247340001"/>
          <site name="tfl_l_tfl_l-P4" pos="0.011925499668840002 -0.047374971678100002 -0.038239147669179997"/>
          <site name="tibant_l_tibant_l-P1" pos="0.017004879157420001 -0.15159990936992002 -0.017903878388459998"/>
          <site name="tibant_l_tibant_l-P2" pos="0.027715744600730001 -0.22023584394745999 -0.014146274282240001"/>
          <site name="tibant_l_tibant_l-P3" pos="0.025728161322590003 -0.42279273504919002 0.01458834535356"/>
          <site name="tibpost_l_tibpost_l-P1" pos="-0.0045272730224300006 -0.15067551967863999 -0.01138333008649"/>
          <site name="tibpost_l_tibpost_l-P2" pos="-0.018109092089720003 -0.42233054020354999 0.019340609370250002"/>
          <site name="vasint_l_vasint_l-P5" pos="0.035964215205011002 -0.073026785611120013 -0.00047522640166900002"/>
          <site name="vaslat_l_vaslat_l-P5" pos="0.035931088817042003 -0.073234773291658006 -0.0056474579361130003"/>
          <site name="vasmed_l_vasmed_l-P5" pos="0.035224392540369999 -0.073454315843337004 0.0074931046588740001"/>
        </body>
        <body name="patella_l" pos="-0.009258 -0.4737 0.003157" euler="-0 0 0">
          <inertial mass="0.063731339850426574" pos="0.0018 0.0264 0" fullinertia="2.1219135193819521e-06 9.6927826617064097e-06 9.6927826617064097e-06 0 0 0"/>
          <geom name="patella_l_geom_1" type="mesh" mesh="patella_l_geom_1_l_patella" rgba="1 1 1 1" group="0"/>
          <joint name="patellofemoral_l_translation1" range="-0.02598 0.05997" limited="true" user="0.05998822768435878" ref="0" axis="1 0 0" type="slide"/>
          <joint name="patellofemoral_l_translation2" range="-0.04738 -0.01254" limited="true" user="-0.012573525423024118" ref="0" axis="0 1 0" type="slide"/>
          <joint name="patellofemoral_l_translation3" limited="false" ref="0" axis="0 0 1" type="slide"/>
          <joint name="patellofemoral_l_rotation1" range="-1.786 0.001137" limited="true" user="0.010505984997239537" ref="0" axis="0 0 1" type="hinge"/>
          <site name="recfem_l_recfem_l-P2" pos="0.01 0.049000000000000002 -0.00069999999999999999"/>
          <site name="recfem_l_recfem_l-P3" pos="0.0121 0.043700000000000003 0.001"/>
          <site name="recfem_l_recfem_l-P4" pos="0.0050000000000000001 0.00247 -3.0000000000000001e-05"/>
          <site name="vasint_l_vasint_l-P3" pos="0.0057999999999999996 0.048000000000000001 0.00059999999999999995"/>
          <site name="vasint_l_vasint_l-P4" pos="0.0050000000000000001 0.00247 0.00038999999999999999"/>
          <site name="vaslat_l_vaslat_l-P3" pos="0.0103 0.042299999999999997 -0.0141"/>
          <site name="vaslat_l_vaslat_l-P4" pos="0.0050000000000000001 0.00247 -0.0073299999999999997"/>
          <site name="vasmed_l_vasmed_l-P3" pos="0.0063 0.044499999999999998 0.017000000000000001"/>
          <site name="vasmed_l_vasmed_l-P4" pos="0.0050000000000000001 0.00247 0.0085000000000000006"/>
        </body>
        <site name="addbrev_l_addbrev_l-P2" pos="-0.0022887870224000003 -0.1370205325012 -0.028587011016839997"/>
        <site name="AB_at_femshaft_l_cylinder_addbrev_l_1_sidesite" pos="0.001134 -0.123 -0.01713" size="0.0005"/>
        <site name="addlong_l_addlong_l-P2" pos="0.012885870936112001 -0.27795427851535798 -0.018173991341227998"/>
        <site name="AL_at_femshaft_l_cylinder_addlong_l_1_sidesite" pos="0.01289 -0.278 -0.01817" size="0.0005"/>
        <site name="addmagDist_l_addmagDist_l-P2" pos="0.012874427001000001 -0.30481262526750003 -0.02215780371988"/>
        <site name="AMdist_at_femshaft_l_cylinder_addmagDist_l_1_sidesite" pos="0.01287 -0.3048 -0.02216" size="0.0005"/>
        <site name="addmagIsch_l_addmagIsch_l-P2" pos="0.0055045327888720002 -0.45050725419059801 0.037576420505268"/>
        <site name="AMisch_at_condyles_l_cylinder_addmagIsch_l_1_sidesite" pos="0.005505 -0.4505 0.03758" size="0.0005"/>
        <site name="addmagMid_l_addmagMid_l-P2" pos="0.0027694322971039999 -0.18857741083215998 -0.033546685217351997"/>
        <site name="AMmid_at_femshaft_l_cylinder_addmagMid_l_1_sidesite" pos="0.002769 -0.1886 -0.03355" size="0.0005"/>
        <site name="addmagProx_l_addmagProx_l-P2" pos="-0.017474888916024001 -0.091571518585123995 -0.036761288865831999"/>
        <site name="AMprox_at_femshaft_l_cylinder_addmagProx_l_1_sidesite" pos="-0.0186 -0.08463 -0.02342" size="0.0005"/>
        <site name="bfsh_l_bfsh_l-P1" pos="0.0057219675560000009 -0.24512741026274001 -0.02686490191944"/>
        <site name="gaslat_l_gaslat_l-P1" pos="-0.0034331805336000002 -0.44287822962676004 -0.031801614665319992"/>
        <site name="Gastroc_at_condyles_l_cylinder_gaslat_l_1_sidesite" pos="-0.01005 -0.4991 -0.0285" size="0.0005"/>
        <site name="gasmed_l_gasmed_l-P1" pos="0.0091551480896000011 -0.43985913314792002 0.023879912817279997"/>
        <site name="Gastroc_at_condyles_l_cylinder_gasmed_l_1_sidesite" pos="0.001139 -0.4964 0.02099" size="0.0005"/>
        <site name="glmax1_l_glmax1_l-P3" pos="-0.050811071897280007 -0.037854825080839996 -0.034671796494319999"/>
        <site name="glmax1_l_glmax1_l-P4" pos="-0.03169970026024 -0.06572340796244 -0.053959418385199992"/>
        <site name="glmax2_l_glmax2_l-P3" pos="-0.051497708004000005 -0.06781355167856 -0.028931432836319996"/>
        <site name="glmax2_l_glmax2_l-P4" pos="-0.017852538774720001 -0.11797700086544 -0.048104247454039996"/>
        <site name="glmax3_l_glmax3_l-P3" pos="-0.032157457664720002 -0.1306339822575 -0.010791883677039999"/>
        <site name="glmax3_l_glmax3_l-P4" pos="-0.0068663610672000004 -0.16477299628746001 -0.047185789268759992"/>
        <site name="glmed1_l_glmed1_l-P2" pos="-0.016021509156800003 -0.0209014371612 -0.067736291164399984"/>
        <site name="glmed2_l_glmed2_l-P2" pos="-0.025176657246399999 -0.011611909534000001 -0.064292072969599989"/>
        <site name="glmed3_l_glmed3_l-P2" pos="-0.035361759496080003 -0.0054575974809800004 -0.059470167496879993"/>
        <site name="glmin1_l_glmin1_l-P2" pos="0.0057219675560000009 -0.017417864301000001 -0.064292072969599989"/>
        <site name="glmin2_l_glmin2_l-P2" pos="0.0045775740448000006 -0.0104507185806 -0.059699782043199992"/>
        <site name="glmin3_l_glmin3_l-P2" pos="-0.0045775740448000006 -0.0011611909534000001 -0.058551709311599989"/>
        <site name="iliacus_l_iliacus_l-P3" pos="-0.0026321050757600003 -0.065607288867100003 -0.015958210969239998"/>
        <site name="iliacus_l_iliacus_l-P4" pos="-0.013961600836640001 -0.073967863731580014 -0.022502225539359998"/>
        <site name="piri_l_piri_l-P3" pos="-0.016937023965760002 -0.0041802874322400003 -0.050170778370919995"/>
        <site name="psoas_l_psoas_l-P3" pos="-0.015105994347840001 -0.054227617523779997 -0.0052811345653599991"/>
        <site name="psoas_l_psoas_l-P4" pos="-0.026893247513200002 -0.060846405958160002 -0.01010304003808"/>
        <site name="KnExt_at_fem_l_cylinder_recfem_l_3_sidesite" pos="-0.01969 -0.4646 0.01532" size="0.0005"/>
        <site name="KnExt_at_fem_l_cylinder_recfem_l_2_sidesite" pos="0.002842 -0.43 0.004157" size="0.0005"/>
        <site name="sart_l_sart_l-P2" pos="-0.0034331805336000002 -0.41431293217311999 0.048333862000359995"/>
        <site name="tfl_l_tfl_l-P2" pos="0.03364516922928 -0.1155384998633 -0.068539942076519991"/>
        <site name="tfl_l_tfl_l-P3" pos="0.01224501056984 -0.47028233612700004 -0.037197556503839997"/>
        <site name="vasint_l_vasint_l-P1" pos="0.033187411824800006 -0.22341313943416 -0.035590254679599996"/>
        <site name="vasint_l_vasint_l-P2" pos="0.038337182625200007 -0.24199219468856001 -0.032720072850599996"/>
        <site name="KnExt_at_fem_l_cylinder_vasint_l_3_sidesite" pos="-0.01984 -0.4635 0.01488" size="0.0005"/>
        <site name="KnExt_at_fem_l_cylinder_vasint_l_2_sidesite" pos="-0.003458 -0.4257 0.003757" size="0.0005"/>
        <site name="vaslat_l_vaslat_l-P1" pos="0.0054930888537600003 -0.21528480276036002 -0.040067738332839997"/>
        <site name="vaslat_l_vaslat_l-P2" pos="0.030784185451280002 -0.30086457602594002 -0.046956174722439993"/>
        <site name="KnExt_at_fem_l_cylinder_vaslat_l_3_sidesite" pos="-0.02412 -0.4647 -0.01157" size="0.0005"/>
        <site name="KnExt_at_fem_l_cylinder_vaslat_l_2_sidesite" pos="0.001042 -0.4314 -0.01094" size="0.0005"/>
        <site name="vasmed_l_vasmed_l-P1" pos="0.016021509156800003 -0.24373398111866001 -0.021583767354079998"/>
        <site name="vasmed_l_vasmed_l-P2" pos="0.040740408998720001 -0.32153377499645996 -0.0010332654584399999"/>
        <site name="KnExt_at_fem_l_cylinder_vasmed_l_4_sidesite" pos="-0.01078 -0.4741 0.02262" size="0.0005"/>
        <site name="KnExt_at_fem_l_cylinder_vasmed_l_3_sidesite" pos="-0.01078 -0.4741 0.02262" size="0.0005"/>
      </body>
      <body name="torso" pos="-0.1016 0.08169 0" euler="-0 0 0">
        <inertial mass="32.5218685392" pos="-0.0300000000 0.3200000000 0.0000000000" fullinertia="1.4006500400 0.7176609734 1.3597086927 0.0000000000 0.0000000000 0.0000000000"/>
        <geom name="torso_geom_1" type="mesh" mesh="torso_geom_1_hat_spine" rgba="1 1 1 1" group="0"/>
        <geom name="torso_geom_2" type="mesh" mesh="torso_geom_2_hat_jaw" rgba="1 1 1 1" group="0"/>
        <geom name="torso_geom_3" type="mesh" mesh="torso_geom_3_hat_skull" rgba="1 1 1 1" group="0"/>
        <geom name="torso_geom_4" type="mesh" mesh="torso_geom_4_hat_ribs_scap" rgba="1 1 1 1" group="0"/>
        <joint name="lumbar_extension" range="-1.571 1.571" limited="true" user="0.0" ref="0" axis="0 0 1" type="hinge"/>
        <joint name="lumbar_bending" range="-1.571 1.571" limited="true" user="0.0" ref="0" axis="1 0 0" type="hinge"/>
        <joint name="lumbar_rotation" range="-1.571 1.571" limited="true" user="0.0" ref="0" axis="0 1 0" type="hinge"/>
      </body>
      <site name="addbrev_r_addbrev_r-P1" pos="-0.019276653611819999 -0.094218798507799989 0.017157186102980001"/>
      <site name="addlong_r_addlong_r-P1" pos="-0.0076501065119159994 -0.089106927524930005 0.021034264521056001"/>
      <site name="addmagDist_r_addmagDist_r-P1" pos="-0.074724787090007988 -0.12796717027117899 0.044363581209134001"/>
      <site name="addmagIsch_r_addmagIsch_r-P1" pos="-0.090448884643523991 -0.13006203504651198 0.046469235867226996"/>
      <site name="addmagMid_r_addmagMid_r-P1" pos="-0.053147046031331996 -0.12103106297677499 0.031796499440198002"/>
      <site name="addmagProx_r_addmagProx_r-P1" pos="-0.031266530308595997 -0.107800338079935 0.015207505864005001"/>
      <site name="bflh_r_bflh_r-P1" pos="-0.10496188354079998 -0.11937722236466999 0.065286435430819995"/>
      <site name="glmax1_r_glmax1_r-P1" pos="-0.12423853715262 0.034580303707650001 0.062723998545310009"/>
      <site name="glmax1_r_glmax1_r-P2" pos="-0.12686258424114 -0.024256328977539997 0.08678862320922999"/>
      <site name="Gmax1_at_pelvis_r_cylinder_glmax1_r_2_sidesite" pos="-0.114 -0.08577 0.1094" size="0.0005"/>
      <site name="glmax2_r_glmax2_r-P1" pos="-0.13291807752234 0.0087202505001899994 0.051471558308939999"/>
      <site name="glmax2_r_glmax2_r-P2" pos="-0.13564304949887998 -0.061041753501329996 0.09057657338781"/>
      <site name="Gmax2_at_pelvis_r_cylinder_glmax2_r_2_sidesite" pos="-0.1265 -0.08952 0.09872" size="0.0005"/>
      <site name="Gmax2_at_pelvis_r_cylinder_glmax2_r_1_sidesite" pos="-0.1356 -0.06104 0.09058" size="0.0005"/>
      <site name="glmax3_r_glmax3_r-P1" pos="-0.13120235442600001 -0.052622201294249993 0.010026926943299999"/>
      <site name="glmax3_r_glmax3_r-P2" pos="-0.12847738244946 -0.12659398139931 0.048463480225949998"/>
      <site name="glmed1_r_glmed1_r-P1" pos="-0.049591871960469332 0.026214131386522715 0.12844312388145268"/>
      <site name="glmed2_r_glmed2_r-P1" pos="-0.085510958322109032 0.05476108527069036 0.091338085631819249"/>
      <site name="glmed3_r_glmed3_r-P1" pos="-0.10078944584746266 0.015595605416340252 0.071192995796019953"/>
      <site name="glmin1_r_glmin1_r-P1" pos="-0.02985311226329436 -0.00010846853759947579 0.13197052215161448"/>
      <site name="glmin2_r_glmin2_r-P1" pos="-0.062169729480328416 0.010023543581283382 0.11268631635039729"/>
      <site name="glmin3_r_glmin3_r-P1" pos="-0.079629736647779989 -0.015536078477349998 0.088905418897259988"/>
      <site name="grac_r_grac_r-P1" pos="-0.047798026966271993 -0.12962101088328398 0.027362369525271997"/>
      <site name="iliacus_r_iliacus_r-P1" pos="-0.061059557252099994 0.03097192419033 0.093918882368909995"/>
      <site name="iliacus_r_iliacus_r-P2" pos="-0.013624859882699999 -0.055829649754089994 0.084226186323720004"/>
      <site name="IL_at_brim_r_cylinder_iliacus_r_2_sidesite" pos="-0.02078 -0.08914 0.09129" size="0.0005"/>
      <site name="piri_r_piri_r-P1" pos="-0.10275162849316199 -0.0065451995133610002 0.015051531444886999"/>
      <site name="piri_r_piri_r-P2" pos="-0.102963570758004 -0.030731365555841998 0.067871154376204001"/>
      <site name="psoas_r_psoas_r-P1" pos="-0.061160482140119994 0.062144313909399992 0.043450016754299998"/>
      <site name="psoas_r_psoas_r-P2" pos="-0.020689602044099999 -0.06555222789798 0.073085156386720002"/>
      <site name="PS_at_brim_r_cylinder_psoas_r_2_sidesite" pos="-0.0338 -0.09099 0.07983" size="0.0005"/>
      <site name="recfem_r_recfem_r-P1" pos="-0.024221973124799998 -0.038890312575559999 0.10394580931220999"/>
      <site name="sart_r_sart_r-P1" pos="-0.019680353163899999 -0.015636311241719998 0.11764927613472"/>
      <site name="semimem_r_semimem_r-P1" pos="-0.099612864475739984 -0.1142653513818 0.068405923813180003"/>
      <site name="semiten_r_semiten_r-P1" pos="-0.10476003376475999 -0.12559165375560999 0.057376304175549994"/>
      <site name="tfl_r_tfl_r-P1" pos="-0.020527905992313366 0.010876604440755737 0.14405078289757492"/>
      <site name="addbrev_l_addbrev_l-P1" pos="-0.019276653611819999 -0.094218798507799989 -0.017157186102980001"/>
      <site name="addlong_l_addlong_l-P1" pos="-0.0076501065119159994 -0.089106927524930005 -0.021034264521056001"/>
      <site name="addmagDist_l_addmagDist_l-P1" pos="-0.074724787090007988 -0.12796717027117899 -0.044363581209134001"/>
      <site name="addmagIsch_l_addmagIsch_l-P1" pos="-0.090448884643523991 -0.13006203504651198 -0.046469235867226996"/>
      <site name="addmagMid_l_addmagMid_l-P1" pos="-0.053147046031331996 -0.12103106297677499 -0.031796499440198002"/>
      <site name="addmagProx_l_addmagProx_l-P1" pos="-0.031266530308595997 -0.107800338079935 -0.015207505864005001"/>
      <site name="bflh_l_bflh_l-P1" pos="-0.10496188354079998 -0.11937722236466999 -0.065286435430819995"/>
      <site name="glmax1_l_glmax1_l-P1" pos="-0.12423853715262 0.034580303707650001 -0.062723998545310009"/>
      <site name="glmax1_l_glmax1_l-P2" pos="-0.12686258424114 -0.024256328977539997 -0.08678862320922999"/>
      <site name="Gmax1_at_pelvis_l_cylinder_glmax1_l_2_sidesite" pos="-0.114 -0.08577 -0.1094" size="0.0005"/>
      <site name="glmax2_l_glmax2_l-P1" pos="-0.13291807752234 0.0087202505001899994 -0.051471558308939999"/>
      <site name="glmax2_l_glmax2_l-P2" pos="-0.13564304949887998 -0.061041753501329996 -0.09057657338781"/>
      <site name="Gmax2_at_pelvis_l_cylinder_glmax2_l_2_sidesite" pos="-0.1265 -0.08952 -0.09872" size="0.0005"/>
      <site name="Gmax2_at_pelvis_l_cylinder_glmax2_l_1_sidesite" pos="-0.1356 -0.06104 -0.09058" size="0.0005"/>
      <site name="glmax3_l_glmax3_l-P1" pos="-0.13120235442600001 -0.052622201294249993 -0.010026926943299999"/>
      <site name="glmax3_l_glmax3_l-P2" pos="-0.12847738244946 -0.12659398139931 -0.048463480225949998"/>
      <site name="glmed1_l_glmed1_l-P1" pos="-0.049453195129799996 0.026060518736199998 -0.1281218442755"/>
      <site name="glmed2_l_glmed2_l-P1" pos="-0.085786154816999999 0.055128020403499997 -0.091356445483400009"/>
      <site name="glmed3_l_glmed3_l-P1" pos="-0.10092488801999999 0.016037242299199998 -0.071302591596799997"/>
      <site name="glmin1_l_glmin1_l-P1" pos="-0.030277466405999997 0 -0.13146415325659999"/>
      <site name="glmin2_l_glmin2_l-P1" pos="-0.062169731020319995 0.010023276437 -0.11252440236370001"/>
      <site name="glmin3_l_glmin3_l-P1" pos="-0.079629736647779989 -0.015536078477349998 -0.088905418897259988"/>
      <site name="grac_l_grac_l-P1" pos="-0.047798026966271993 -0.12962101088328398 -0.027362369525271997"/>
      <site name="iliacus_l_iliacus_l-P1" pos="-0.061059557252099994 0.03097192419033 -0.093918882368909995"/>
      <site name="iliacus_l_iliacus_l-P2" pos="-0.013624859882699999 -0.055829649754089994 -0.084226186323720004"/>
      <site name="IL_at_brim_l_cylinder_iliacus_l_2_sidesite" pos="-0.02078 -0.08914 -0.09129" size="0.0005"/>
      <site name="piri_l_piri_l-P1" pos="-0.10275162849316199 -0.0065451995133610002 -0.015051531444886999"/>
      <site name="piri_l_piri_l-P2" pos="-0.102963570758004 -0.030731365555841998 -0.067871154376204001"/>
      <site name="psoas_l_psoas_l-P1" pos="-0.061160482140119994 0.062144313909399992 -0.043450016754299998"/>
      <site name="psoas_l_psoas_l-P2" pos="-0.020689602044099999 -0.06555222789798 -0.073085156386720002"/>
      <site name="PS_at_brim_l_cylinder_psoas_l_2_sidesite" pos="-0.0338 -0.09099 -0.07983" size="0.0005"/>
      <site name="recfem_l_recfem_l-P1" pos="-0.024221973124799998 -0.038890312575559999 -0.10394580931220999"/>
      <site name="sart_l_sart_l-P1" pos="-0.019680353163899999 -0.015636311241719998 -0.11764927613472"/>
      <site name="semimem_l_semimem_l-P1" pos="-0.099612864475739984 -0.1142653513818 -0.068405923813180003"/>
      <site name="semiten_l_semiten_l-P1" pos="-0.10476003376475999 -0.12559165375560999 -0.057376304175549994"/>
      <site name="tfl_l_tfl_l-P1" pos="-0.020184977603999999 0.011025604080699998 -0.14371928618730001"/>
    </body>
  </worldbody>
  <asset>
    <texture type="skybox" builtin="gradient" rgb1="1 1 1" rgb2="0.6 0.8 1" width="256" height="256"/>
    <mesh name="pelvis_geom_1_r_pelvis" file="Geometry/r_pelvis.stl" scale="1.0092488801999999 1.0023276436999999 1.1141029937"/>
    <mesh name="pelvis_geom_2_l_pelvis" file="Geometry/l_pelvis.stl" scale="1.0092488801999999 1.0023276436999999 1.1141029937"/>
    <mesh name="pelvis_geom_3_sacrum" file="Geometry/sacrum.stl" scale="1.0092488801999999 1.0023276436999999 1.1141029937"/>
    <mesh name="femur_r_geom_1_r_femur" file="Geometry/r_femur.stl" scale="1.1443935112000001 1.1611909534 1.1480727315999999"/>
    <mesh name="tibia_r_geom_1_r_tibia" file="Geometry/r_tibia.stl" scale="1.1042129323000001 1.1554871141 1.1051776783"/>
    <mesh name="tibia_r_geom_2_r_fibula" file="Geometry/r_fibula.stl" scale="1.1042129323000001 1.1554871141 1.1051776783"/>
    <mesh name="talus_r_geom_1_r_talus" file="Geometry/r_talus.stl" scale="1.1548265091000001 1.1828832900999999 1.1696017513999999"/>
    <mesh name="calcn_r_geom_1_r_foot" file="Geometry/r_foot.stl" scale="1.0678354877 1.0524672077999999 1.0677668132"/>
    <mesh name="toes_r_geom_1_r_bofoot" file="Geometry/r_bofoot.stl" scale="1.1177927981 1.1177230919000001 1.1178597991999999"/>
    <mesh name="patella_r_geom_1_r_patella" file="Geometry/r_patella.stl" scale="1 1 1"/>
    <mesh name="femur_l_geom_1_l_femur" file="Geometry/l_femur.stl" scale="1.1443935112000001 1.1611909534 1.1480727315999999"/>
    <mesh name="tibia_l_geom_1_l_tibia" file="Geometry/l_tibia.stl" scale="1.1042129323000001 1.1554871141 1.1051776783"/>
    <mesh name="tibia_l_geom_2_l_fibula" file="Geometry/l_fibula.stl" scale="1.1042129323000001 1.1554871141 1.1051776783"/>
    <mesh name="talus_l_geom_1_l_talus" file="Geometry/l_talus.stl" scale="1.1548265091000001 1.1828832900999999 1.1696017513999999"/>
    <mesh name="calcn_l_geom_1_l_foot" file="Geometry/l_foot.stl" scale="1.0678354877 1.0524672077999999 1.0677668132"/>
    <mesh name="toes_l_geom_1_l_bofoot" file="Geometry/l_bofoot.stl" scale="1.1177927981 1.1177230919000001 1.1178597991999999"/>
    <mesh name="patella_l_geom_1_l_patella" file="Geometry/l_patella.stl" scale="1 1 1"/>
    <mesh name="torso_geom_1_hat_spine" file="Geometry/hat_spine.stl" scale="1.1554201856999999 0.92063895500000004 1.1083830095"/>
    <mesh name="torso_geom_2_hat_jaw" file="Geometry/hat_jaw.stl" scale="1.1554201856999999 0.92063895500000004 1.1083830095"/>
    <mesh name="torso_geom_3_hat_skull" file="Geometry/hat_skull.stl" scale="1.1554201856999999 0.92063895500000004 1.1083830095"/>
    <mesh name="torso_geom_4_hat_ribs_scap" file="Geometry/hat_ribs_scap.stl" scale="1.1554201856999999 0.92063895500000004 1.1083830095"/>
  </asset>
  <tendon>
    <!-- Leave this comment here to make 'tendon' element pretty printed !-->
    <spatial name="addbrev_r_tendon">
      <site site="addbrev_r_addbrev_r-P1"/>
      <geom geom="AB_at_femshaft_r_cylinder" sidesite="AB_at_femshaft_r_cylinder_addbrev_r_1_sidesite"/>
      <site site="addbrev_r_addbrev_r-P2"/>
    </spatial>
    <spatial name="addlong_r_tendon">
      <site site="addlong_r_addlong_r-P1"/>
      <geom geom="AL_at_femshaft_r_cylinder" sidesite="AL_at_femshaft_r_cylinder_addlong_r_1_sidesite"/>
      <site site="addlong_r_addlong_r-P2"/>
    </spatial>
    <spatial name="addmagDist_r_tendon">
      <site site="addmagDist_r_addmagDist_r-P1"/>
      <geom geom="AMdist_at_femshaft_r_cylinder" sidesite="AMdist_at_femshaft_r_cylinder_addmagDist_r_1_sidesite"/>
      <site site="addmagDist_r_addmagDist_r-P2"/>
    </spatial>
    <spatial name="addmagIsch_r_tendon">
      <site site="addmagIsch_r_addmagIsch_r-P1"/>
      <geom geom="AMisch_at_condyles_r_cylinder" sidesite="AMisch_at_condyles_r_cylinder_addmagIsch_r_1_sidesite"/>
      <site site="addmagIsch_r_addmagIsch_r-P2"/>
    </spatial>
    <spatial name="addmagMid_r_tendon">
      <site site="addmagMid_r_addmagMid_r-P1"/>
      <geom geom="AMmid_at_femshaft_r_cylinder" sidesite="AMmid_at_femshaft_r_cylinder_addmagMid_r_1_sidesite"/>
      <site site="addmagMid_r_addmagMid_r-P2"/>
    </spatial>
    <spatial name="addmagProx_r_tendon">
      <site site="addmagProx_r_addmagProx_r-P1"/>
      <geom geom="AMprox_at_femshaft_r_cylinder" sidesite="AMprox_at_femshaft_r_cylinder_addmagProx_r_1_sidesite"/>
      <site site="addmagProx_r_addmagProx_r-P2"/>
    </spatial>
    <spatial name="bflh_r_tendon">
      <site site="bflh_r_bflh_r-P1"/>
      <site site="bflh_r_bflh_r-P2"/>
      <site site="bflh_r_bflh_r-P3"/>
    </spatial>
    <spatial name="bfsh_r_tendon">
      <site site="bfsh_r_bfsh_r-P1"/>
      <site site="bfsh_r_bfsh_r-P2"/>
    </spatial>
    <spatial name="edl_r_tendon">
      <site site="edl_r_edl_r-P1"/>
      <site site="edl_r_edl_r-P2"/>
      <site site="edl_r_edl_r-P3"/>
      <site site="edl_r_edl_r-P4"/>
      <site site="edl_r_edl_r-P5"/>
      <site site="edl_r_edl_r-P6"/>
    </spatial>
    <spatial name="ehl_r_tendon">
      <site site="ehl_r_ehl_r-P1"/>
      <site site="ehl_r_ehl_r-P2"/>
      <site site="ehl_r_ehl_r-P3"/>
      <site site="ehl_r_ehl_r-P4"/>
      <site site="ehl_r_ehl_r-P5"/>
      <site site="ehl_r_ehl_r-P6"/>
      <site site="ehl_r_ehl_r-P7"/>
      <site site="ehl_r_ehl_r-P8"/>
    </spatial>
    <spatial name="fdl_r_tendon">
      <site site="fdl_r_fdl_r-P1"/>
      <site site="fdl_r_fdl_r-P2"/>
      <site site="fdl_r_fdl_r-P3"/>
      <site site="fdl_r_fdl_r-P4"/>
      <site site="fdl_r_fdl_r-P5"/>
      <site site="fdl_r_fdl_r-P6"/>
      <site site="fdl_r_fdl_r-P7"/>
      <site site="fdl_r_fdl_r-P8"/>
    </spatial>
    <spatial name="fhl_r_tendon">
      <site site="fhl_r_fhl_r-P1"/>
      <site site="fhl_r_fhl_r-P2"/>
      <site site="fhl_r_fhl_r-P3"/>
      <site site="fhl_r_fhl_r-P4"/>
      <site site="fhl_r_fhl_r-P5"/>
      <site site="fhl_r_fhl_r-P6"/>
      <site site="fhl_r_fhl_r-P7"/>
    </spatial>
    <spatial name="gaslat_r_tendon">
      <site site="gaslat_r_gaslat_r-P1"/>
      <geom geom="Gastroc_at_condyles_r_cylinder" sidesite="Gastroc_at_condyles_r_cylinder_gaslat_r_1_sidesite"/>
      <site site="gaslat_r_gaslat_r-P2"/>
    </spatial>
    <spatial name="gasmed_r_tendon">
      <site site="gasmed_r_gasmed_r-P1"/>
      <geom geom="Gastroc_at_condyles_r_cylinder" sidesite="Gastroc_at_condyles_r_cylinder_gasmed_r_1_sidesite"/>
      <site site="gasmed_r_gasmed_r-P2"/>
    </spatial>
    <spatial name="glmax1_r_tendon">
      <site site="glmax1_r_glmax1_r-P1"/>
      <site site="glmax1_r_glmax1_r-P2"/>
      <geom geom="Gmax1_at_pelvis_r_cylinder" sidesite="Gmax1_at_pelvis_r_cylinder_glmax1_r_2_sidesite"/>
      <site site="glmax1_r_glmax1_r-P3"/>
      <site site="glmax1_r_glmax1_r-P4"/>
    </spatial>
    <spatial name="glmax2_r_tendon">
      <site site="glmax2_r_glmax2_r-P1"/>
      <geom geom="Gmax2_at_pelvis_r_cylinder" sidesite="Gmax2_at_pelvis_r_cylinder_glmax2_r_1_sidesite"/>
      <site site="glmax2_r_glmax2_r-P2"/>
      <geom geom="Gmax2_at_pelvis_r_cylinder" sidesite="Gmax2_at_pelvis_r_cylinder_glmax2_r_2_sidesite"/>
      <site site="glmax2_r_glmax2_r-P3"/>
      <site site="glmax2_r_glmax2_r-P4"/>
    </spatial>
    <spatial name="glmax3_r_tendon">
      <site site="glmax3_r_glmax3_r-P1"/>
      <site site="glmax3_r_glmax3_r-P2"/>
      <site site="glmax3_r_glmax3_r-P3"/>
      <site site="glmax3_r_glmax3_r-P4"/>
    </spatial>
    <spatial name="glmed1_r_tendon">
      <site site="glmed1_r_glmed1_r-P1"/>
      <site site="glmed1_r_glmed1_r-P2_0"/>
    </spatial>
    <spatial name="glmed2_r_tendon">
      <site site="glmed2_r_glmed2_r-P1"/>
      <site site="glmed2_r_glmed2_r-P2_0"/>
    </spatial>
    <spatial name="glmed3_r_tendon">
      <site site="glmed3_r_glmed3_r-P1"/>
      <site site="glmed3_r_glmed3_r-P2_0"/>
    </spatial>
    <spatial name="glmin1_r_tendon">
      <site site="glmin1_r_glmin1_r-P1"/>
      <site site="glmin1_r_glmin1_r-P2"/>
    </spatial>
    <spatial name="glmin2_r_tendon">
      <site site="glmin2_r_glmin2_r-P1"/>
      <site site="glmin2_r_glmin2_r-P2"/>
    </spatial>
    <spatial name="glmin3_r_tendon">
      <site site="glmin3_r_glmin3_r-P1"/>
      <site site="glmin3_r_glmin3_r-P2"/>
    </spatial>
    <spatial name="grac_r_tendon">
      <site site="grac_r_grac_r-P1"/>
      <geom geom="GR_at_condyles_r_cylinder" sidesite="GR_at_condyles_r_cylinder_grac_r_1_sidesite"/>
      <site site="grac_r_grac_r-P2"/>
      <site site="grac_r_grac_r-P3"/>
    </spatial>
    <spatial name="iliacus_r_tendon">
      <site site="iliacus_r_iliacus_r-P1"/>
      <site site="iliacus_r_iliacus_r-P2"/>
      <geom geom="IL_at_brim_r_cylinder" sidesite="IL_at_brim_r_cylinder_iliacus_r_2_sidesite"/>
      <site site="iliacus_r_iliacus_r-P3"/>
      <site site="iliacus_r_iliacus_r-P4"/>
    </spatial>
    <spatial name="perbrev_r_tendon">
      <site site="perbrev_r_perbrev_r-P1"/>
      <site site="perbrev_r_perbrev_r-P2"/>
      <site site="perbrev_r_perbrev_r-P3"/>
      <site site="perbrev_r_perbrev_r-P4"/>
      <site site="perbrev_r_perbrev_r-P5"/>
    </spatial>
    <spatial name="perlong_r_tendon">
      <site site="perlong_r_perlong_r-P1"/>
      <site site="perlong_r_perlong_r-P2"/>
      <site site="perlong_r_perlong_r-P3"/>
      <site site="perlong_r_perlong_r-P4"/>
      <site site="perlong_r_perlong_r-P5"/>
      <site site="perlong_r_perlong_r-P6"/>
      <site site="perlong_r_perlong_r-P7"/>
    </spatial>
    <spatial name="piri_r_tendon">
      <site site="piri_r_piri_r-P1"/>
      <site site="piri_r_piri_r-P2"/>
      <site site="piri_r_piri_r-P3"/>
    </spatial>
    <spatial name="psoas_r_tendon">
      <site site="psoas_r_psoas_r-P1"/>
      <site site="psoas_r_psoas_r-P2"/>
      <geom geom="PS_at_brim_r_cylinder" sidesite="PS_at_brim_r_cylinder_psoas_r_2_sidesite"/>
      <site site="psoas_r_psoas_r-P3"/>
      <site site="psoas_r_psoas_r-P4"/>
    </spatial>
    <spatial name="recfem_r_tendon">
      <site site="recfem_r_recfem_r-P1"/>
      <site site="recfem_r_recfem_r-P2"/>
      <geom geom="KnExt_at_fem_r_cylinder" sidesite="KnExt_at_fem_r_cylinder_recfem_r_2_sidesite"/>
      <site site="recfem_r_recfem_r-P3"/>
      <geom geom="KnExt_at_fem_r_cylinder" sidesite="KnExt_at_fem_r_cylinder_recfem_r_3_sidesite"/>
      <site site="recfem_r_recfem_r-P4"/>
      <site site="recfem_r_recfem_r-P5"/>
    </spatial>
    <spatial name="sart_r_tendon">
      <site site="sart_r_sart_r-P1"/>
      <site site="sart_r_sart_r-P2"/>
      <site site="sart_r_sart_r-P3"/>
      <site site="sart_r_sart_r-P4"/>
      <site site="sart_r_sart_r-P5"/>
    </spatial>
    <spatial name="semimem_r_tendon">
      <site site="semimem_r_semimem_r-P1"/>
      <geom geom="SM_at_condyles_r_cylinder" sidesite="SM_at_condyles_r_cylinder_semimem_r_1_sidesite"/>
      <site site="semimem_r_semimem_r-P2"/>
    </spatial>
    <spatial name="semiten_r_tendon">
      <site site="semiten_r_semiten_r-P1"/>
      <geom geom="ST_at_condyles_r_cylinder" sidesite="ST_at_condyles_r_cylinder_semiten_r_1_sidesite"/>
      <site site="semiten_r_semiten_r-P2"/>
      <site site="semiten_r_semiten_r-P3"/>
    </spatial>
    <spatial name="soleus_r_tendon">
      <site site="soleus_r_soleus_r-P1"/>
      <site site="soleus_r_soleus_r-P2"/>
    </spatial>
    <spatial name="tfl_r_tendon">
      <site site="tfl_r_tfl_r-P1"/>
      <site site="tfl_r_tfl_r-P2"/>
      <site site="tfl_r_tfl_r-P3"/>
      <site site="tfl_r_tfl_r-P4"/>
    </spatial>
    <spatial name="tibant_r_tendon">
      <site site="tibant_r_tibant_r-P1"/>
      <site site="tibant_r_tibant_r-P2"/>
      <site site="tibant_r_tibant_r-P3"/>
      <site site="tibant_r_tibant_r-P4"/>
    </spatial>
    <spatial name="tibpost_r_tendon">
      <site site="tibpost_r_tibpost_r-P1"/>
      <site site="tibpost_r_tibpost_r-P2"/>
      <site site="tibpost_r_tibpost_r-P3"/>
      <site site="tibpost_r_tibpost_r-P4"/>
    </spatial>
    <spatial name="vasint_r_tendon">
      <site site="vasint_r_vasint_r-P1"/>
      <site site="vasint_r_vasint_r-P2"/>
      <geom geom="KnExt_at_fem_r_cylinder" sidesite="KnExt_at_fem_r_cylinder_vasint_r_2_sidesite"/>
      <site site="vasint_r_vasint_r-P3"/>
      <geom geom="KnExt_at_fem_r_cylinder" sidesite="KnExt_at_fem_r_cylinder_vasint_r_3_sidesite"/>
      <site site="vasint_r_vasint_r-P4"/>
      <site site="vasint_r_vasint_r-P5"/>
    </spatial>
    <spatial name="vaslat_r_tendon">
      <site site="vaslat_r_vaslat_r-P1"/>
      <site site="vaslat_r_vaslat_r-P2"/>
      <geom geom="KnExt_at_fem_r_cylinder" sidesite="KnExt_at_fem_r_cylinder_vaslat_r_2_sidesite"/>
      <site site="vaslat_r_vaslat_r-P3"/>
      <geom geom="KnExt_at_fem_r_cylinder" sidesite="KnExt_at_fem_r_cylinder_vaslat_r_3_sidesite"/>
      <site site="vaslat_r_vaslat_r-P4"/>
      <site site="vaslat_r_vaslat_r-P5"/>
    </spatial>
    <spatial name="vasmed_r_tendon">
      <site site="vasmed_r_vasmed_r-P1"/>
      <site site="vasmed_r_vasmed_r-P2"/>
      <site site="vasmed_r_vasmed_r-P3"/>
      <geom geom="KnExt_at_fem_r_cylinder" sidesite="KnExt_at_fem_r_cylinder_vasmed_r_3_sidesite"/>
      <site site="vasmed_r_vasmed_r-P4"/>
      <geom geom="KnExt_at_fem_r_cylinder" sidesite="KnExt_at_fem_r_cylinder_vasmed_r_4_sidesite"/>
      <site site="vasmed_r_vasmed_r-P5"/>
    </spatial>
    <spatial name="addbrev_l_tendon">
      <site site="addbrev_l_addbrev_l-P1"/>
      <geom geom="AB_at_femshaft_l_cylinder" sidesite="AB_at_femshaft_l_cylinder_addbrev_l_1_sidesite"/>
      <site site="addbrev_l_addbrev_l-P2"/>
    </spatial>
    <spatial name="addlong_l_tendon">
      <site site="addlong_l_addlong_l-P1"/>
      <geom geom="AL_at_femshaft_l_cylinder" sidesite="AL_at_femshaft_l_cylinder_addlong_l_1_sidesite"/>
      <site site="addlong_l_addlong_l-P2"/>
    </spatial>
    <spatial name="addmagDist_l_tendon">
      <site site="addmagDist_l_addmagDist_l-P1"/>
      <geom geom="AMdist_at_femshaft_l_cylinder" sidesite="AMdist_at_femshaft_l_cylinder_addmagDist_l_1_sidesite"/>
      <site site="addmagDist_l_addmagDist_l-P2"/>
    </spatial>
    <spatial name="addmagIsch_l_tendon">
      <site site="addmagIsch_l_addmagIsch_l-P1"/>
      <geom geom="AMisch_at_condyles_l_cylinder" sidesite="AMisch_at_condyles_l_cylinder_addmagIsch_l_1_sidesite"/>
      <site site="addmagIsch_l_addmagIsch_l-P2"/>
    </spatial>
    <spatial name="addmagMid_l_tendon">
      <site site="addmagMid_l_addmagMid_l-P1"/>
      <geom geom="AMmid_at_femshaft_l_cylinder" sidesite="AMmid_at_femshaft_l_cylinder_addmagMid_l_1_sidesite"/>
      <site site="addmagMid_l_addmagMid_l-P2"/>
    </spatial>
    <spatial name="addmagProx_l_tendon">
      <site site="addmagProx_l_addmagProx_l-P1"/>
      <geom geom="AMprox_at_femshaft_l_cylinder" sidesite="AMprox_at_femshaft_l_cylinder_addmagProx_l_1_sidesite"/>
      <site site="addmagProx_l_addmagProx_l-P2"/>
    </spatial>
    <spatial name="bflh_l_tendon">
      <site site="bflh_l_bflh_l-P1"/>
      <site site="bflh_l_bflh_l-P2"/>
      <site site="bflh_l_bflh_l-P3"/>
    </spatial>
    <spatial name="bfsh_l_tendon">
      <site site="bfsh_l_bfsh_l-P1"/>
      <site site="bfsh_l_bfsh_l-P2"/>
    </spatial>
    <spatial name="edl_l_tendon">
      <site site="edl_l_edl_l-P1"/>
      <site site="edl_l_edl_l-P2"/>
      <site site="edl_l_edl_l-P3"/>
      <site site="edl_l_edl_l-P4"/>
      <site site="edl_l_edl_l-P5"/>
      <site site="edl_l_edl_l-P6"/>
    </spatial>
    <spatial name="ehl_l_tendon">
      <site site="ehl_l_ehl_l-P1"/>
      <site site="ehl_l_ehl_l-P2"/>
      <site site="ehl_l_ehl_l-P3"/>
      <site site="ehl_l_ehl_l-P4"/>
      <site site="ehl_l_ehl_l-P5"/>
      <site site="ehl_l_ehl_l-P6"/>
      <site site="ehl_l_ehl_l-P7"/>
      <site site="ehl_l_ehl_l-P8"/>
    </spatial>
    <spatial name="fdl_l_tendon">
      <site site="fdl_l_fdl_l-P1"/>
      <site site="fdl_l_fdl_l-P2"/>
      <site site="fdl_l_fdl_l-P3"/>
      <site site="fdl_l_fdl_l-P4"/>
      <site site="fdl_l_fdl_l-P5"/>
      <site site="fdl_l_fdl_l-P6"/>
      <site site="fdl_l_fdl_l-P7"/>
      <site site="fdl_l_fdl_l-P8"/>
    </spatial>
    <spatial name="fhl_l_tendon">
      <site site="fhl_l_fhl_l-P1"/>
      <site site="fhl_l_fhl_l-P2"/>
      <site site="fhl_l_fhl_l-P3"/>
      <site site="fhl_l_fhl_l-P4"/>
      <site site="fhl_l_fhl_l-P5"/>
      <site site="fhl_l_fhl_l-P6"/>
      <site site="fhl_l_fhl_l-P7"/>
    </spatial>
    <spatial name="gaslat_l_tendon">
      <site site="gaslat_l_gaslat_l-P1"/>
      <geom geom="Gastroc_at_condyles_l_cylinder" sidesite="Gastroc_at_condyles_l_cylinder_gaslat_l_1_sidesite"/>
      <site site="gaslat_l_gaslat_l-P2"/>
    </spatial>
    <spatial name="gasmed_l_tendon">
      <site site="gasmed_l_gasmed_l-P1"/>
      <geom geom="Gastroc_at_condyles_l_cylinder" sidesite="Gastroc_at_condyles_l_cylinder_gasmed_l_1_sidesite"/>
      <site site="gasmed_l_gasmed_l-P2"/>
    </spatial>
    <spatial name="glmax1_l_tendon">
      <site site="glmax1_l_glmax1_l-P1"/>
      <site site="glmax1_l_glmax1_l-P2"/>
      <geom geom="Gmax1_at_pelvis_l_cylinder" sidesite="Gmax1_at_pelvis_l_cylinder_glmax1_l_2_sidesite"/>
      <site site="glmax1_l_glmax1_l-P3"/>
      <site site="glmax1_l_glmax1_l-P4"/>
    </spatial>
    <spatial name="glmax2_l_tendon">
      <site site="glmax2_l_glmax2_l-P1"/>
      <geom geom="Gmax2_at_pelvis_l_cylinder" sidesite="Gmax2_at_pelvis_l_cylinder_glmax2_l_1_sidesite"/>
      <site site="glmax2_l_glmax2_l-P2"/>
      <geom geom="Gmax2_at_pelvis_l_cylinder" sidesite="Gmax2_at_pelvis_l_cylinder_glmax2_l_2_sidesite"/>
      <site site="glmax2_l_glmax2_l-P3"/>
      <site site="glmax2_l_glmax2_l-P4"/>
    </spatial>
    <spatial name="glmax3_l_tendon">
      <site site="glmax3_l_glmax3_l-P1"/>
      <site site="glmax3_l_glmax3_l-P2"/>
      <site site="glmax3_l_glmax3_l-P3"/>
      <site site="glmax3_l_glmax3_l-P4"/>
    </spatial>
    <spatial name="glmed1_l_tendon">
      <site site="glmed1_l_glmed1_l-P1"/>
      <site site="glmed1_l_glmed1_l-P2"/>
    </spatial>
    <spatial name="glmed2_l_tendon">
      <site site="glmed2_l_glmed2_l-P1"/>
      <site site="glmed2_l_glmed2_l-P2"/>
    </spatial>
    <spatial name="glmed3_l_tendon">
      <site site="glmed3_l_glmed3_l-P1"/>
      <site site="glmed3_l_glmed3_l-P2"/>
    </spatial>
    <spatial name="glmin1_l_tendon">
      <site site="glmin1_l_glmin1_l-P1"/>
      <site site="glmin1_l_glmin1_l-P2"/>
    </spatial>
    <spatial name="glmin2_l_tendon">
      <site site="glmin2_l_glmin2_l-P1"/>
      <site site="glmin2_l_glmin2_l-P2"/>
    </spatial>
    <spatial name="glmin3_l_tendon">
      <site site="glmin3_l_glmin3_l-P1"/>
      <site site="glmin3_l_glmin3_l-P2"/>
    </spatial>
    <spatial name="grac_l_tendon">
      <site site="grac_l_grac_l-P1"/>
      <geom geom="GR_at_condyles_l_cylinder" sidesite="GR_at_condyles_l_cylinder_grac_l_1_sidesite"/>
      <site site="grac_l_grac_l-P2"/>
      <site site="grac_l_grac_l-P3"/>
    </spatial>
    <spatial name="iliacus_l_tendon">
      <site site="iliacus_l_iliacus_l-P1"/>
      <site site="iliacus_l_iliacus_l-P2"/>
      <geom geom="IL_at_brim_l_cylinder" sidesite="IL_at_brim_l_cylinder_iliacus_l_2_sidesite"/>
      <site site="iliacus_l_iliacus_l-P3"/>
      <site site="iliacus_l_iliacus_l-P4"/>
    </spatial>
    <spatial name="perbrev_l_tendon">
      <site site="perbrev_l_perbrev_l-P1"/>
      <site site="perbrev_l_perbrev_l-P2"/>
      <site site="perbrev_l_perbrev_l-P3"/>
      <site site="perbrev_l_perbrev_l-P4"/>
      <site site="perbrev_l_perbrev_l-P5"/>
    </spatial>
    <spatial name="perlong_l_tendon">
      <site site="perlong_l_perlong_l-P1"/>
      <site site="perlong_l_perlong_l-P2"/>
      <site site="perlong_l_perlong_l-P3"/>
      <site site="perlong_l_perlong_l-P4"/>
      <site site="perlong_l_perlong_l-P5"/>
      <site site="perlong_l_perlong_l-P6"/>
      <site site="perlong_l_perlong_l-P7"/>
    </spatial>
    <spatial name="piri_l_tendon">
      <site site="piri_l_piri_l-P1"/>
      <site site="piri_l_piri_l-P2"/>
      <site site="piri_l_piri_l-P3"/>
    </spatial>
    <spatial name="psoas_l_tendon">
      <site site="psoas_l_psoas_l-P1"/>
      <site site="psoas_l_psoas_l-P2"/>
      <geom geom="PS_at_brim_l_cylinder" sidesite="PS_at_brim_l_cylinder_psoas_l_2_sidesite"/>
      <site site="psoas_l_psoas_l-P3"/>
      <site site="psoas_l_psoas_l-P4"/>
    </spatial>
    <spatial name="recfem_l_tendon">
      <site site="recfem_l_recfem_l-P1"/>
      <site site="recfem_l_recfem_l-P2"/>
      <geom geom="KnExt_at_fem_l_cylinder" sidesite="KnExt_at_fem_l_cylinder_recfem_l_2_sidesite"/>
      <site site="recfem_l_recfem_l-P3"/>
      <geom geom="KnExt_at_fem_l_cylinder" sidesite="KnExt_at_fem_l_cylinder_recfem_l_3_sidesite"/>
      <site site="recfem_l_recfem_l-P4"/>
      <site site="recfem_l_recfem_l-P5"/>
    </spatial>
    <spatial name="sart_l_tendon">
      <site site="sart_l_sart_l-P1"/>
      <site site="sart_l_sart_l-P2"/>
      <site site="sart_l_sart_l-P3"/>
      <site site="sart_l_sart_l-P4"/>
      <site site="sart_l_sart_l-P5"/>
    </spatial>
    <spatial name="semimem_l_tendon">
      <site site="semimem_l_semimem_l-P1"/>
      <geom geom="SM_at_condyles_l_cylinder" sidesite="SM_at_condyles_l_cylinder_semimem_l_1_sidesite"/>
      <site site="semimem_l_semimem_l-P2"/>
    </spatial>
    <spatial name="semiten_l_tendon">
      <site site="semiten_l_semiten_l-P1"/>
      <geom geom="ST_at_condyles_l_cylinder" sidesite="ST_at_condyles_l_cylinder_semiten_l_1_sidesite"/>
      <site site="semiten_l_semiten_l-P2"/>
      <site site="semiten_l_semiten_l-P3"/>
    </spatial>
    <spatial name="soleus_l_tendon">
      <site site="soleus_l_soleus_l-P1"/>
      <site site="soleus_l_soleus_l-P2"/>
    </spatial>
    <spatial name="tfl_l_tendon">
      <site site="tfl_l_tfl_l-P1"/>
      <site site="tfl_l_tfl_l-P2"/>
      <site site="tfl_l_tfl_l-P3"/>
      <site site="tfl_l_tfl_l-P4"/>
    </spatial>
    <spatial name="tibant_l_tendon">
      <site site="tibant_l_tibant_l-P1"/>
      <site site="tibant_l_tibant_l-P2"/>
      <site site="tibant_l_tibant_l-P3"/>
      <site site="tibant_l_tibant_l-P4"/>
    </spatial>
    <spatial name="tibpost_l_tendon">
      <site site="tibpost_l_tibpost_l-P1"/>
      <site site="tibpost_l_tibpost_l-P2"/>
      <site site="tibpost_l_tibpost_l-P3"/>
      <site site="tibpost_l_tibpost_l-P4"/>
    </spatial>
    <spatial name="vasint_l_tendon">
      <site site="vasint_l_vasint_l-P1"/>
      <site site="vasint_l_vasint_l-P2"/>
      <geom geom="KnExt_at_fem_l_cylinder" sidesite="KnExt_at_fem_l_cylinder_vasint_l_2_sidesite"/>
      <site site="vasint_l_vasint_l-P3"/>
      <geom geom="KnExt_at_fem_l_cylinder" sidesite="KnExt_at_fem_l_cylinder_vasint_l_3_sidesite"/>
      <site site="vasint_l_vasint_l-P4"/>
      <site site="vasint_l_vasint_l-P5"/>
    </spatial>
    <spatial name="vaslat_l_tendon">
      <site site="vaslat_l_vaslat_l-P1"/>
      <site site="vaslat_l_vaslat_l-P2"/>
      <geom geom="KnExt_at_fem_l_cylinder" sidesite="KnExt_at_fem_l_cylinder_vaslat_l_2_sidesite"/>
      <site site="vaslat_l_vaslat_l-P3"/>
      <geom geom="KnExt_at_fem_l_cylinder" sidesite="KnExt_at_fem_l_cylinder_vaslat_l_3_sidesite"/>
      <site site="vaslat_l_vaslat_l-P4"/>
      <site site="vaslat_l_vaslat_l-P5"/>
    </spatial>
    <spatial name="vasmed_l_tendon">
      <site site="vasmed_l_vasmed_l-P1"/>
      <site site="vasmed_l_vasmed_l-P2"/>
      <site site="vasmed_l_vasmed_l-P3"/>
      <geom geom="KnExt_at_fem_l_cylinder" sidesite="KnExt_at_fem_l_cylinder_vasmed_l_3_sidesite"/>
      <site site="vasmed_l_vasmed_l-P4"/>
      <geom geom="KnExt_at_fem_l_cylinder" sidesite="KnExt_at_fem_l_cylinder_vasmed_l_4_sidesite"/>
      <site site="vasmed_l_vasmed_l-P5"/>
    </spatial>
  </tendon>
  <actuator>
    <!-- Leave this comment here to make 'actuator' element pretty printed !-->
    <motor name="lumbar_ext" ctrllimited="false" joint="lumbar_extension" class="motor"/>
    <motor name="lumbar_bend" ctrllimited="false" joint="lumbar_bending" class="motor"/>
    <motor name="lumbar_rot" ctrllimited="false" joint="lumbar_rotation" class="motor"/>
    <muscle name="addbrev_r" lengthrange="0.01 1" force="625.81967213114797" tendon="addbrev_r_tendon" class="muscle" timeconst="0.01 0.04"/>
    <muscle name="addlong_r" lengthrange="0.01 1" force="916.79999999999995" tendon="addlong_r_tendon" class="muscle" timeconst="0.01 0.04"/>
    <muscle name="addmagDist_r" lengthrange="0.01 1" force="597.29508196721395" tendon="addmagDist_r_tendon" class="muscle" timeconst="0.01 0.04"/>
    <muscle name="addmagIsch_r" lengthrange="0.01 1" force="597.29508196721395" tendon="addmagIsch_r_tendon" class="muscle" timeconst="0.01 0.04"/>
    <muscle name="addmagMid_r" lengthrange="0.01 1" force="597.29508196721395" tendon="addmagMid_r_tendon" class="muscle" timeconst="0.01 0.04"/>
    <muscle name="addmagProx_r" lengthrange="0.01 1" force="597.29508196721395" tendon="addmagProx_r_tendon" class="muscle" timeconst="0.01 0.04"/>
    <muscle name="bflh_r" lengthrange="0.01 1" force="1313.18360655738" tendon="bflh_r_tendon" class="muscle" timeconst="0.01 0.04"/>
    <muscle name="bfsh_r" lengthrange="0.01 1" force="557.11475409835998" tendon="bfsh_r_tendon" class="muscle" timeconst="0.01 0.04"/>
    <muscle name="edl_r" lengthrange="0.01 1" force="603.49815560000002" tendon="edl_r_tendon" class="muscle" timeconst="0.01 0.04"/>
    <muscle name="ehl_r" lengthrange="0.01 1" force="285.86754739999998" tendon="ehl_r_tendon" class="muscle" timeconst="0.01 0.04"/>
    <muscle name="fdl_r" lengthrange="0.01 1" force="423.17704918032803" tendon="fdl_r_tendon" class="muscle" timeconst="0.01 0.04"/>
    <muscle name="fhl_r" lengthrange="0.01 1" force="907.83934426229405" tendon="fhl_r_tendon" class="muscle" timeconst="0.01 0.04"/>
    <muscle name="gaslat_r" lengthrange="0.01 1" force="1575.0590163934401" tendon="gaslat_r_tendon" class="muscle" timeconst="0.01 0.04"/>
    <muscle name="gasmed_r" lengthrange="0.01 1" force="3115.5147540983598" tendon="gasmed_r_tendon" class="muscle" timeconst="0.01 0.04"/>
    <muscle name="glmax1_r" lengthrange="0.01 1" force="983.78360655737799" tendon="glmax1_r_tendon" class="muscle" timeconst="0.01 0.04"/>
    <muscle name="glmax2_r" lengthrange="0.01 1" force="1406.0459016393499" tendon="glmax2_r_tendon" class="muscle" timeconst="0.01 0.04"/>
    <muscle name="glmax3_r" lengthrange="0.01 1" force="947.75409836065603" tendon="glmax3_r_tendon" class="muscle" timeconst="0.01 0.04"/>
    <muscle name="glmed1_r" lengthrange="0.01 1" force="1093.4667688" tendon="glmed1_r_tendon" class="muscle" timeconst="0.01 0.04"/>
    <muscle name="glmed2_r" lengthrange="0.01 1" force="765.09166159999995" tendon="glmed2_r_tendon" class="muscle" timeconst="0.01 0.04"/>
    <muscle name="glmed3_r" lengthrange="0.01 1" force="871.19926420000002" tendon="glmed3_r_tendon" class="muscle" timeconst="0.01 0.04"/>
    <muscle name="glmin1_r" lengthrange="0.01 1" force="374.04590163934398" tendon="glmin1_r_tendon" class="muscle" timeconst="0.01 0.04"/>
    <muscle name="glmin2_r" lengthrange="0.01 1" force="394.81967213114802" tendon="glmin2_r_tendon" class="muscle" timeconst="0.01 0.04"/>
    <muscle name="glmin3_r" lengthrange="0.01 1" force="446.77377049180399" tendon="glmin3_r_tendon" class="muscle" timeconst="0.01 0.04"/>
    <muscle name="grac_r" lengthrange="0.01 1" force="281.31147540983602" tendon="grac_r_tendon" class="muscle" timeconst="0.01 0.04"/>
    <muscle name="iliacus_r" lengthrange="0.01 1" force="1021.14098360656" tendon="iliacus_r_tendon" class="muscle" timeconst="0.01 0.04"/>
    <muscle name="perbrev_r" lengthrange="0.01 1" force="521.20159880000006" tendon="perbrev_r_tendon" class="muscle" timeconst="0.01 0.04"/>
    <muscle name="perlong_r" lengthrange="0.01 1" force="1115.3714213999999" tendon="perlong_r_tendon" class="muscle" timeconst="0.01 0.04"/>
    <muscle name="piri_r" lengthrange="0.01 1" force="1029.7868852459001" tendon="piri_r_tendon" class="muscle" timeconst="0.01 0.04"/>
    <muscle name="psoas_r" lengthrange="0.01 1" force="1426.79016393443" tendon="psoas_r_tendon" class="muscle" timeconst="0.01 0.04"/>
    <muscle name="recfem_r" lengthrange="0.01 1" force="2191.7409836065599" tendon="recfem_r_tendon" class="muscle" timeconst="0.01 0.04"/>
    <muscle name="sart_r" lengthrange="0.01 1" force="249.41311475409799" tendon="sart_r_tendon" class="muscle" timeconst="0.01 0.04"/>
    <muscle name="semimem_r" lengthrange="0.01 1" force="2200.9868852458999" tendon="semimem_r_tendon" class="muscle" timeconst="0.01 0.04"/>
    <muscle name="semiten_r" lengthrange="0.01 1" force="591.29508196721395" tendon="semiten_r_tendon" class="muscle" timeconst="0.01 0.04"/>
    <muscle name="soleus_r" lengthrange="0.01 1" force="6194.8426229508204" tendon="soleus_r_tendon" class="muscle" timeconst="0.01 0.04"/>
    <muscle name="tfl_r" lengthrange="0.01 1" force="411.20655737704999" tendon="tfl_r_tendon" class="muscle" timeconst="0.01 0.04"/>
    <muscle name="tibant_r" lengthrange="0.01 1" force="1227.4524590163901" tendon="tibant_r_tendon" class="muscle" timeconst="0.01 0.04"/>
    <muscle name="tibpost_r" lengthrange="0.01 1" force="1730.1540983606501" tendon="tibpost_r_tendon" class="muscle" timeconst="0.01 0.04"/>
    <muscle name="vasint_r" lengthrange="0.01 1" force="1697.36065573771" tendon="vasint_r_tendon" class="muscle" timeconst="0.01 0.04"/>
    <muscle name="vaslat_r" lengthrange="0.01 1" force="5148.7672131147601" tendon="vaslat_r_tendon" class="muscle" timeconst="0.01 0.04"/>
    <muscle name="vasmed_r" lengthrange="0.01 1" force="2747.82295081966" tendon="vasmed_r_tendon" class="muscle" timeconst="0.01 0.04"/>
    <muscle name="addbrev_l" lengthrange="0.01 1" force="625.81967213114797" tendon="addbrev_l_tendon" class="muscle" timeconst="0.01 0.04"/>
    <muscle name="addlong_l" lengthrange="0.01 1" force="916.79999999999995" tendon="addlong_l_tendon" class="muscle" timeconst="0.01 0.04"/>
    <muscle name="addmagDist_l" lengthrange="0.01 1" force="597.29508196721395" tendon="addmagDist_l_tendon" class="muscle" timeconst="0.01 0.04"/>
    <muscle name="addmagIsch_l" lengthrange="0.01 1" force="597.29508196721395" tendon="addmagIsch_l_tendon" class="muscle" timeconst="0.01 0.04"/>
    <muscle name="addmagMid_l" lengthrange="0.01 1" force="597.29508196721395" tendon="addmagMid_l_tendon" class="muscle" timeconst="0.01 0.04"/>
    <muscle name="addmagProx_l" lengthrange="0.01 1" force="597.29508196721395" tendon="addmagProx_l_tendon" class="muscle" timeconst="0.01 0.04"/>
    <muscle name="bflh_l" lengthrange="0.01 1" force="1313.18360655738" tendon="bflh_l_tendon" class="muscle" timeconst="0.01 0.04"/>
    <muscle name="bfsh_l" lengthrange="0.01 1" force="557.11475409835998" tendon="bfsh_l_tendon" class="muscle" timeconst="0.01 0.04"/>
    <muscle name="edl_l" lengthrange="0.01 1" force="603.49815560000002" tendon="edl_l_tendon" class="muscle" timeconst="0.01 0.04"/>
    <muscle name="ehl_l" lengthrange="0.01 1" force="285.86754739999998" tendon="ehl_l_tendon" class="muscle" timeconst="0.01 0.04"/>
    <muscle name="fdl_l" lengthrange="0.01 1" force="423.17704918032803" tendon="fdl_l_tendon" class="muscle" timeconst="0.01 0.04"/>
    <muscle name="fhl_l" lengthrange="0.01 1" force="907.83934426229405" tendon="fhl_l_tendon" class="muscle" timeconst="0.01 0.04"/>
    <muscle name="gaslat_l" lengthrange="0.01 1" force="1575.0590163934401" tendon="gaslat_l_tendon" class="muscle" timeconst="0.01 0.04"/>
    <muscle name="gasmed_l" lengthrange="0.01 1" force="3115.5147540983598" tendon="gasmed_l_tendon" class="muscle" timeconst="0.01 0.04"/>
    <muscle name="glmax1_l" lengthrange="0.01 1" force="983.78360655737799" tendon="glmax1_l_tendon" class="muscle" timeconst="0.01 0.04"/>
    <muscle name="glmax2_l" lengthrange="0.01 1" force="1406.0459016393499" tendon="glmax2_l_tendon" class="muscle" timeconst="0.01 0.04"/>
    <muscle name="glmax3_l" lengthrange="0.01 1" force="947.75409836065603" tendon="glmax3_l_tendon" class="muscle" timeconst="0.01 0.04"/>
    <muscle name="glmed1_l" lengthrange="0.01 1" force="1093.4667688" tendon="glmed1_l_tendon" class="muscle" timeconst="0.01 0.04"/>
    <muscle name="glmed2_l" lengthrange="0.01 1" force="765.09166159999995" tendon="glmed2_l_tendon" class="muscle" timeconst="0.01 0.04"/>
    <muscle name="glmed3_l" lengthrange="0.01 1" force="871.19926420000002" tendon="glmed3_l_tendon" class="muscle" timeconst="0.01 0.04"/>
    <muscle name="glmin1_l" lengthrange="0.01 1" force="374.04590163934398" tendon="glmin1_l_tendon" class="muscle" timeconst="0.01 0.04"/>
    <muscle name="glmin2_l" lengthrange="0.01 1" force="394.81967213114802" tendon="glmin2_l_tendon" class="muscle" timeconst="0.01 0.04"/>
    <muscle name="glmin3_l" lengthrange="0.01 1" force="446.77377049180399" tendon="glmin3_l_tendon" class="muscle" timeconst="0.01 0.04"/>
    <muscle name="grac_l" lengthrange="0.01 1" force="281.31147540983602" tendon="grac_l_tendon" class="muscle" timeconst="0.01 0.04"/>
    <muscle name="iliacus_l" lengthrange="0.01 1" force="1021.14098360656" tendon="iliacus_l_tendon" class="muscle" timeconst="0.01 0.04"/>
    <muscle name="perbrev_l" lengthrange="0.01 1" force="521.20159880000006" tendon="perbrev_l_tendon" class="muscle" timeconst="0.01 0.04"/>
    <muscle name="perlong_l" lengthrange="0.01 1" force="1115.3714213999999" tendon="perlong_l_tendon" class="muscle" timeconst="0.01 0.04"/>
    <muscle name="piri_l" lengthrange="0.01 1" force="1029.7868852459001" tendon="piri_l_tendon" class="muscle" timeconst="0.01 0.04"/>
    <muscle name="psoas_l" lengthrange="0.01 1" force="1426.79016393443" tendon="psoas_l_tendon" class="muscle" timeconst="0.01 0.04"/>
    <muscle name="recfem_l" lengthrange="0.01 1" force="2191.7409836065599" tendon="recfem_l_tendon" class="muscle" timeconst="0.01 0.04"/>
    <muscle name="sart_l" lengthrange="0.01 1" force="249.41311475409799" tendon="sart_l_tendon" class="muscle" timeconst="0.01 0.04"/>
    <muscle name="semimem_l" lengthrange="0.01 1" force="2200.9868852458999" tendon="semimem_l_tendon" class="muscle" timeconst="0.01 0.04"/>
    <muscle name="semiten_l" lengthrange="0.01 1" force="591.29508196721395" tendon="semiten_l_tendon" class="muscle" timeconst="0.01 0.04"/>
    <muscle name="soleus_l" lengthrange="0.01 1" force="6194.8426229508204" tendon="soleus_l_tendon" class="muscle" timeconst="0.01 0.04"/>
    <muscle name="tfl_l" lengthrange="0.01 1" force="411.20655737704999" tendon="tfl_l_tendon" class="muscle" timeconst="0.01 0.04"/>
    <muscle name="tibant_l" lengthrange="0.01 1" force="1227.4524590163901" tendon="tibant_l_tendon" class="muscle" timeconst="0.01 0.04"/>
    <muscle name="tibpost_l" lengthrange="0.01 1" force="1730.1540983606501" tendon="tibpost_l_tendon" class="muscle" timeconst="0.01 0.04"/>
    <muscle name="vasint_l" lengthrange="0.01 1" force="1697.36065573771" tendon="vasint_l_tendon" class="muscle" timeconst="0.01 0.04"/>
    <muscle name="vaslat_l" lengthrange="0.01 1" force="5148.7672131147601" tendon="vaslat_l_tendon" class="muscle" timeconst="0.01 0.04"/>
    <muscle name="vasmed_l" lengthrange="0.01 1" force="2747.82295081966" tendon="vasmed_l_tendon" class="muscle" timeconst="0.01 0.04"/>
  </actuator>
  <equality>
    <!-- Leave this comment here to make 'equality' element pretty printed !-->
    <joint joint1="walker_knee_r_translation1" joint2="knee_angle_r" polycoef="1.107e-07 0.003633 -0.00268 0.0006521 6.6e-07" solimp="0.9999 0.9999 0.001 0.5 2" active="true"/>
    <joint joint1="walker_knee_r_translation2" joint2="knee_angle_r" polycoef="8.832e-11 0.00675 -0.001442 -3.006e-06 7.168e-07" solimp="0.9999 0.9999 0.001 0.5 2" active="true"/>
    <joint joint1="walker_knee_r_rotation2" joint2="knee_angle_r" polycoef="-1.473e-08 0.0791 -0.03285 -0.02522 0.01083" solimp="0.9999 0.9999 0.001 0.5 2" active="true"/>
    <joint joint1="walker_knee_r_rotation3" joint2="knee_angle_r" polycoef="1.089e-08 0.3695 -0.1695 0.02516 3.505e-07" solimp="0.9999 0.9999 0.001 0.5 2" active="true"/>
    <joint name="mtp_angle_r_locked" active="true" joint1="mtp_angle_r" polycoef="0.0 0 0 0 0" solimp="0.9999 0.9999 0.001 0.5 2"/>
    <joint joint1="patellofemoral_r_translation1" joint2="knee_angle_r" polycoef="0.05999 -0.01719 -0.03897 0.01527 -0.001006" solimp="0.9999 0.9999 0.001 0.5 2" active="true"/>
    <joint joint1="patellofemoral_r_translation2" joint2="knee_angle_r" polycoef="-0.01257 -0.05665 0.01077 0.01529 -0.00406" solimp="0.9999 0.9999 0.001 0.5 2" active="true"/>
    <joint joint1="patellofemoral_r_rotation1" joint2="knee_angle_r" polycoef="0.01051 0.02476 -1.316 0.7163 -0.1383" solimp="0.9999 0.9999 0.001 0.5 2" active="true"/>
    <joint name="patellofemoral_r_translation3_locked" active="true" joint1="patellofemoral_r_translation3" polycoef="0.0031572000118999994 0 0 0 0" solimp="0.9999 0.9999 0.001 0.5 2"/>
    <joint joint1="walker_knee_l_translation1" joint2="knee_angle_l" polycoef="1.107e-07 0.003633 -0.00268 0.0006521 6.6e-07" solimp="0.9999 0.9999 0.001 0.5 2" active="true"/>
    <joint joint1="walker_knee_l_translation2" joint2="knee_angle_l" polycoef="-8.832e-11 -0.00675 0.001442 3.006e-06 -7.168e-07" solimp="0.9999 0.9999 0.001 0.5 2" active="true"/>
    <joint joint1="walker_knee_l_rotation2" joint2="knee_angle_l" polycoef="-1.473e-08 0.0791 -0.03285 -0.02522 0.01083" solimp="0.9999 0.9999 0.001 0.5 2" active="true"/>
    <joint joint1="walker_knee_l_rotation3" joint2="knee_angle_l" polycoef="-1.089e-08 -0.3695 0.1695 -0.02516 -3.505e-07" solimp="0.9999 0.9999 0.001 0.5 2" active="true"/>
    <joint name="mtp_angle_l_locked" active="true" joint1="mtp_angle_l" polycoef="0.0 0 0 0 0" solimp="0.9999 0.9999 0.001 0.5 2"/>
    <joint joint1="patellofemoral_l_translation1" joint2="knee_angle_l" polycoef="0.05999 -0.01719 -0.03897 0.01527 -0.001006" solimp="0.9999 0.9999 0.001 0.5 2" active="true"/>
    <joint joint1="patellofemoral_l_translation2" joint2="knee_angle_l" polycoef="-0.01257 -0.05665 0.01077 0.01529 -0.00406" solimp="0.9999 0.9999 0.001 0.5 2" active="true"/>
    <joint joint1="patellofemoral_l_rotation1" joint2="knee_angle_l" polycoef="0.01051 0.02476 -1.316 0.7163 -0.1383" solimp="0.9999 0.9999 0.001 0.5 2" active="true"/>
    <joint name="patellofemoral_l_translation3_locked" active="true" joint1="patellofemoral_l_translation3" polycoef="-0.0031572000118999994 0 0 0 0" solimp="0.9999 0.9999 0.001 0.5 2"/>
  </equality>
  <contact>
    <!-- Leave this comment here to make 'contact' element pretty printed !-->
  </contact>
  <keyframe>
    <key name="default-pose" qpos="0 0.93 0 0 0 0 0 0 0 1.107e-07 8.832e-11 0 -1.473e-08 1.089e-08 0 0 0 0.05999 -0.01257 0.003157 0.01051 0 -0 -0 1.107e-07 -8.832e-11 0 -1.473e-08 -1.089e-08 0 0 0 0.05999 -0.01257 -0.003157 0.01051 0 0 0"/>
  </keyframe>
</mujoco>
